Workbook

Sheet Hesaplama
B1: TOPLAM DEĞER KAYBI | H1: =IF(AND($C$3="F",((2.5*(C7*F9*(1+(J5+J7+J9+J11))*J3))<=0.3)),IF(AND(Tablolar!U5>0,Tablolar!U5<=500),Tablolar!U4+500,IF(Tablolar!U5<>0,Tablolar!U4+1000,0)),IF(AND($C$3="F",((2.5*(C7*F9*(1+(J5+J7+J9+J11))*J3))>0.3)),IF(AND(Tablolar!W5>0,Tablolar!W5<=500),Tablolar!W4+500,IF(Tablolar!W5<>0,Tablolar!W4+1000,0)),IF(AND($B$3="OTOBÜS",((0.5*(C7*F9*(1+(J5+J7+J9+J11))*J3))<=0.3)),IF(AND(Tablolar!U9>0,Tablolar!U9<=500),Tablolar!U8+500,IF(Tablolar!U9<>0,Tablolar!U8+1000,0)),IF(AND($B$3="OTOBÜS",((0.5*(C7*F9*(1+(J5+J7+J9+J11))*J3))>0.3)),IF(AND(Tablolar!W5>0,Tablolar!W5<=500),Tablolar!W4+500,IF(Tablolar!W5<>0,Tablolar!W4+1000,0)),IF((C7*F9*(1+(J5+J7+J9+J11))*J3)<=0.3,IF(AND(Tablolar!U13>0,Tablolar!U13<=500),Tablolar!U12+500,IF(Tablolar!U13<>0,Tablolar!U12+1000,0)),IF(AND(Tablolar!W5>0,Tablolar!W5<=500),Tablolar!W4+500,IF(Tablolar!W5<>0,Tablolar!W4+1000,0))))))) -> 0
B3: ARAÇ GRUBU | C3: =IF(B3="ARAÇ GRUBU",0,VLOOKUP(B3,Tablolar!B3:C16,2,FALSE)) -> 0 | E3: HASAR MİKTARI | F3: 0 | H3: HASAR KATSAYISI | J3: =IF($F$3=0,0,(((C64+H64+K64)+(((F3/C5)*100)*0.1))/100)) -> 0
B5: RAYİÇ BEDEL | C5: 0 | E5: TİCARİ YA DA KIRALIK MI? | F5: HAYIR | H5: G1-TİCARİ YA DA KİRALIK PARAMETRESİ | J5: =IF($F$5="EVET",-0.05,0) -> 0
B7: RAYİÇ BEDEL KATSAYISI | C7: =IF($C$5=0,0,VLOOKUP(Tablolar!$B$27,Tablolar!$B$19:$C$26,2,FALSE)) -> 0 | E7: SBM GEÇMİŞ HASAR ADEDİ | F7: 0 | H7: G2-SBM GEÇMİŞ HASAR KATSAYISI | J7: =IF($F$7= 0,0,IF($F$7<=5,$F$7*-0.03,-0.15)) -> 0
B9: =IF($C$3="D",Tablolar!E19,Tablolar!E12) -> KİLOMETRE | C9: 0 | E9: =IF($C$3="D","ÇALIŞMA ZAMANI KATSAYISI","KİLOMETRE KATSAYISI") -> KİLOMETRE KATSAYISI | F9: =(IF($C$9=0,1,VLOOKUP(C3,Tablolar!$E$13:$R$20, IF(AND(C3="D", $C$9<=500),2, IF(AND(C3="D", $C$9>=501, $C$9<=1000),3, IF(AND(C3="D", $C$9>=1001, $C$9<=2000),4, IF(AND(C3="D", $C$9>=2001, $C$9<=3000),5, IF(AND(C3="D", $C$9>=3001, $C$9<=4000),6, IF(AND(C3="D", $C$9>=4001, $C$9<=5000),7, IF(AND(OR(C3="A",C3="F"), $C$9<=19999),2, IF(AND(OR(C3="A",C3="F"), $C$9>=20000, $C$9<=49999),3, IF(AND(OR(C3="A",C3="F"), $C$9>=50000, $C$9<=99999),4, IF(AND(OR(C3="A",C3="F"), $C$9>=100000, $C$9<=149999),5, IF(AND(OR(C3="B",C3="C", C3="Ç",C3="E"), $C$9<=49999),2, IF(AND(OR(C3="B",C3="C", C3="Ç", C3="E"), $C$9>=50000, $C$9<=149999),5, IF(AND(OR(C3="A",C3="F"), $C$9>=150000, $C$9<=199999),6, IF(AND(OR(C3="B",C3="C", C3="Ç", C3="E"), $C$9>=150000, $C$9<=299999),6, IF(AND(OR(C3="A",C3="F"), $C$9>=200000, $C$9<=299999),7, IF(AND(OR(C3="A",C3="F", C3="B",C3="C", C3="Ç", C3="E"), $C$9>=300000, $C$9<=499999),8, IF(AND(OR(C3="A",C3="F"), $C$9>=500000),9, IF(AND(OR( C3="B",C3="C", C3="Ç", C3="E"), $C$9>=500000, $C$9<=749999),9, IF(AND(OR( C3="B",C3="C", C3="Ç", C3="E"), $C$9>=750000, $C$9<=999999),10, IF(AND(OR( C3="B",C3="C", C3="Ç", C3="E"), $C$9>=1000000),11,1)))))))))))))))))))), FALSE))) -> 1 | H9: G3-KİLOMETRE ALT SINIRA YAKINLIK KATSAYISI | J9: =IF(AND(OR(C3="A",C3="F", C3="C",C3="B", C3="Ç",C3="E"),($C$9<=1000)),0.05,IF(AND(OR(C3="A",C3="F"),(AND($C$9>=20000,$C$9<=21000))),0.05,IF(AND(OR(C3="A",C3="F", C3="C",C3="B", C3="Ç",C3="E"),(AND($C$9>=50000,$C$9<=51000))),0.05,IF(AND(OR(C3="A",C3="F"),(AND($C$9>=100000,$C$9<=101000))),0.05,IF(AND(OR(C3="A",C3="F", C3="C",C3="B", C3="Ç",C3="E"),(AND($C$9>=150000,$C$9<=151000))),0.05,IF(AND(OR(C3="A",C3="F"),(AND($C$9>=200000,$C$9<=201000))),0.05,IF(AND(OR(C3="A",C3="F", C3="C",C3="B", C3="Ç",C3="E"),(AND($C$9>=300000,$C$9<=301000))),0.05, IF(AND(OR( C3="C",C3="B", C3="Ç",C3="E"),(AND($C$9>=500000,$C$9<=501000))),0.05, IF(AND(OR( C3="C",C3="B", C3="Ç",C3="E"),(AND($C$9>=750000,$C$9<=751000))),0.05, IF(AND(OR( C3="C",C3="B", C3="Ç",C3="E"),(AND($C$9>=1000000,$C$9<=1001000))),0.05,0)))))))))) -> 0
B11: MODEL YILI | C11: 0 | E11: HASAR TARİHİ (Örn: 01.01.1990) | F11: =TODAY() -> 46204
A13: HATIRLATMA : Onarılan parçanın, parça fiyatı ve işçilik bedeli iskontosuz KDV hariç olacaktır
A15: SEÇ | B15: DEĞİŞMESİ GEREKEN PARÇALAR | C15: KATSAYI | D15: SEÇ | E15: ONARILAN PARÇALAR | F15: YENİ FİYAT | G15: İŞÇİLİK | H15: KATSAYI | I15: BOYANACAK PARÇALAR | J15: SEÇ | K15: KATSAYI
B16: =(IF($C$3=0,"",IF($C$3="A",Tablolar!B34,IF($C$3="B",Tablolar!B70, IF(OR($C$3="C",$C$3="Ç"),Tablolar!B119, IF($C$3="D",Tablolar!B155, IF($C$3="E",Tablolar!B192, IF($C$3="F",Tablolar!B228,0)))))))) | C16: =(IF($C$3=0,0,VLOOKUP(B16,IF($C$3="A",Tablolar!$B$34:$C$66,IF($C$3="B",Tablolar!$B$70:$C$113, IF(OR($C$3="C",$C$3="Ç"),Tablolar!$B$119:$C$150, IF($C$3="D",Tablolar!$B$155:$C$186, IF($C$3="E",Tablolar!$B$192:$C$223, IF($C$3="F",Tablolar!$B$228:$C$259,Tablolar!$B$264:$C$295)))))),2,FALSE)))*IF(Tablolar!A34=TRUE,1,0) -> 0 | E16: =(IF($C$3=0,"",IF($C$3="A",Tablolar!B34,IF($C$3="B",Tablolar!B70, IF(OR($C$3="C",$C$3="Ç"),Tablolar!B119, IF($C$3="D",Tablolar!B155, IF($C$3="E",Tablolar!B192, IF($C$3="F",Tablolar!B228,0)))))))) | H16: =IF(AND(Tablolar!D34=TRUE,F16=0),IF(Tablolar!D34=TRUE,VLOOKUP(E16,IF($C$3="A",Tablolar!$E$34:$H$66,IF($C$3="B",Tablolar!$E$70:$H$113,IF(OR($C$3="C",$C$3="Ç"),Tablolar!$E$119:$H$150,IF($C$3="D",Tablolar!$E$155:$H$186,IF($C$3="E",Tablolar!$E$192:$H$223,IF($C$3="F",Tablolar!$E$228:$H$259,Tablolar!$E$266:$H$295)))))),4,FALSE),0),(IF(OR($C$3=0,F16=0),0,VLOOKUP(E16,IF($C$3="A",Tablolar!$E$34:$H$66,IF($C$3="B",Tablolar!$E$70:$H$113,IF(OR($C$3="C",$C$3="Ç"),Tablolar!$E$119:$H$150,IF($C$3="D",Tablolar!$E$155:$H$186,IF($C$3="E",Tablolar!$E$192:$H$223,IF($C$3="F",Tablolar!$E$228:$H$259,Tablolar!$E$264:$H$295)))))),IF(G16/F16<0.15,2,IF(AND(G16/F16>=0.15,G16/F16<0.3),3,IF(G16/F16>=0.3,4,0))),FALSE)))) -> 0 | I16: =(IF($C$3=0,"",IF($C$3="A",Tablolar!B34,IF($C$3="B",Tablolar!B70, IF(OR($C$3="C",$C$3="Ç"),Tablolar!B119, IF($C$3="D",Tablolar!B155, IF($C$3="E",Tablolar!B192, IF($C$3="F",Tablolar!B228,0)))))))) | K16: =IF(J16="TAM", IF($C$3="A",Tablolar!K34, IF($C$3="B",Tablolar!K70, IF(OR($C$3="C",$C$3="Ç"),Tablolar!K119, IF($C$3="D",Tablolar!K155, IF($C$3="E",Tablolar!K192, IF($C$3="F",Tablolar!K228, Tablolar!K160)))))), IF(J16="LOKAL", IF($C$3="A",Tablolar!L34, IF($C$3="B",Tablolar!L70, IF(OR($C$3="C",$C$3="Ç"),Tablolar!L119, IF($C$3="D",Tablolar!L155, IF($C$3="E",Tablolar!L192, IF($C$3="F",Tablolar!L228, Tablolar!L264)))))),0)) -> 0
B17: =(IF($C$3=0,"",IF($C$3="A",Tablolar!B35,IF($C$3="B",Tablolar!B71, IF(OR($C$3="C",$C$3="Ç"),Tablolar!B120, IF($C$3="D",Tablolar!B156, IF($C$3="E",Tablolar!B193, IF($C$3="F",Tablolar!B229,0)))))))) | C17: =(IF($C$3=0,0,VLOOKUP(B17,IF($C$3="A",Tablolar!$B$34:$C$66,IF($C$3="B",Tablolar!$B$70:$C$113, IF(OR($C$3="C",$C$3="Ç"),Tablolar!$B$119:$C$150, IF($C$3="D",Tablolar!$B$155:$C$186, IF($C$3="E",Tablolar!$B$192:$C$223, IF($C$3="F",Tablolar!$B$228:$C$259,Tablolar!$B$264:$C$295)))))),2,FALSE)))*IF(Tablolar!A35=TRUE,1,0) -> 0 | E17: =(IF($C$3=0,"",IF($C$3="A",Tablolar!B35,IF($C$3="B",Tablolar!B71, IF(OR($C$3="C",$C$3="Ç"),Tablolar!B120, IF($C$3="D",Tablolar!B156, IF($C$3="E",Tablolar!B193, IF($C$3="F",Tablolar!B229,0)))))))) | H17: =IF(AND(Tablolar!D35=TRUE,F17=0),IF(Tablolar!D35=TRUE,VLOOKUP(E17,IF($C$3="A",Tablolar!$E$34:$H$66,IF($C$3="B",Tablolar!$E$70:$H$113,IF(OR($C$3="C",$C$3="Ç"),Tablolar!$E$119:$H$150,IF($C$3="D",Tablolar!$E$155:$H$186,IF($C$3="E",Tablolar!$E$192:$H$223,IF($C$3="F",Tablolar!$E$228:$H$259,Tablolar!$E$266:$H$295)))))),4,FALSE),0),(IF(OR($C$3=0,F17=0),0,VLOOKUP(E17,IF($C$3="A",Tablolar!$E$34:$H$66,IF($C$3="B",Tablolar!$E$70:$H$113,IF(OR($C$3="C",$C$3="Ç"),Tablolar!$E$119:$H$150,IF($C$3="D",Tablolar!$E$155:$H$186,IF($C$3="E",Tablolar!$E$192:$H$223,IF($C$3="F",Tablolar!$E$228:$H$259,Tablolar!$E$264:$H$295)))))),IF(G17/F17<0.15,2,IF(AND(G17/F17>=0.15,G17/F17<0.3),3,IF(G17/F17>=0.3,4,0))),FALSE)))) -> 0 | I17: =(IF($C$3=0,"",IF($C$3="A",Tablolar!B35,IF($C$3="B",Tablolar!B71, IF(OR($C$3="C",$C$3="Ç"),Tablolar!B120, IF($C$3="D",Tablolar!B156, IF($C$3="E",Tablolar!B193, IF($C$3="F",Tablolar!B229,0)))))))) | K17: =IF(J17="TAM", IF($C$3="A",Tablolar!K35, IF($C$3="B",Tablolar!K71, IF(OR($C$3="C",$C$3="Ç"),Tablolar!K120, IF($C$3="D",Tablolar!K156, IF($C$3="E",Tablolar!K193, IF($C$3="F",Tablolar!K229, Tablolar!K161)))))), IF(J17="LOKAL", IF($C$3="A",Tablolar!L35, IF($C$3="B",Tablolar!L71, IF(OR($C$3="C",$C$3="Ç"),Tablolar!L120, IF($C$3="D",Tablolar!L156, IF($C$3="E",Tablolar!L193, IF($C$3="F",Tablolar!L229, Tablolar!L265)))))),0)) -> 0
B18: =(IF($C$3=0,"",IF($C$3="A",Tablolar!B36,IF($C$3="B",Tablolar!B72, IF(OR($C$3="C",$C$3="Ç"),Tablolar!B121, IF($C$3="D",Tablolar!B157, IF($C$3="E",Tablolar!B194, IF($C$3="F",Tablolar!B230,0)))))))) | C18: =(IF($C$3=0,0,VLOOKUP(B18,IF($C$3="A",Tablolar!$B$34:$C$66,IF($C$3="B",Tablolar!$B$70:$C$113, IF(OR($C$3="C",$C$3="Ç"),Tablolar!$B$119:$C$150, IF($C$3="D",Tablolar!$B$155:$C$186, IF($C$3="E",Tablolar!$B$192:$C$223, IF($C$3="F",Tablolar!$B$228:$C$259,Tablolar!$B$264:$C$295)))))),2,FALSE)))*IF(Tablolar!A36=TRUE,1,0) -> 0 | E18: =(IF($C$3=0,"",IF($C$3="A",Tablolar!B36,IF($C$3="B",Tablolar!B72, IF(OR($C$3="C",$C$3="Ç"),Tablolar!B121, IF($C$3="D",Tablolar!B157, IF($C$3="E",Tablolar!B194, IF($C$3="F",Tablolar!B230,0)))))))) | H18: =IF(AND(Tablolar!D36=TRUE,F18=0),IF(Tablolar!D36=TRUE,VLOOKUP(E18,IF($C$3="A",Tablolar!$E$34:$H$66,IF($C$3="B",Tablolar!$E$70:$H$113,IF(OR($C$3="C",$C$3="Ç"),Tablolar!$E$119:$H$150,IF($C$3="D",Tablolar!$E$155:$H$186,IF($C$3="E",Tablolar!$E$192:$H$223,IF($C$3="F",Tablolar!$E$228:$H$259,Tablolar!$E$264:$H$295)))))),4,FALSE),0),(IF(OR($C$3=0,F18=0),0,VLOOKUP(E18,IF($C$3="A",Tablolar!$E$34:$H$66,IF($C$3="B",Tablolar!$E$70:$H$113,IF(OR($C$3="C",$C$3="Ç"),Tablolar!$E$119:$H$150,IF($C$3="D",Tablolar!$E$155:$H$186,IF($C$3="E",Tablolar!$E$192:$H$223,IF($C$3="F",Tablolar!$E$228:$H$259,Tablolar!$E$264:$H$295)))))),IF(G18/F18<0.15,2,IF(AND(G18/F18>=0.15,G18/F18<0.3),3,IF(G18/F18>=0.3,4,0))),FALSE)))) -> 0 | I18: =(IF($C$3=0,"",IF($C$3="A",Tablolar!B36,IF($C$3="B",Tablolar!B72, IF(OR($C$3="C",$C$3="Ç"),Tablolar!B121, IF($C$3="D",Tablolar!B157, IF($C$3="E",Tablolar!B194, IF($C$3="F",Tablolar!B230,0)))))))) | K18: =IF(J18="TAM", IF($C$3="A",Tablolar!K36, IF($C$3="B",Tablolar!K72, IF(OR($C$3="C",$C$3="Ç"),Tablolar!K121, IF($C$3="D",Tablolar!K157, IF($C$3="E",Tablolar!K194, IF($C$3="F",Tablolar!K230, Tablolar!K162)))))), IF(J18="LOKAL", IF($C$3="A",Tablolar!L36, IF($C$3="B",Tablolar!L72, IF(OR($C$3="C",$C$3="Ç"),Tablolar!L121, IF($C$3="D",Tablolar!L157, IF($C$3="E",Tablolar!L194, IF($C$3="F",Tablolar!L230, Tablolar!L266)))))),0)) -> 0 | M18: =IF(C3=”B”, Tablolar!$E$70:$H$113,Tablolar!$E$119:$H$150) -> #NAME?
B19: =(IF($C$3=0,"",IF($C$3="A",Tablolar!B37,IF($C$3="B",Tablolar!B73, IF(OR($C$3="C",$C$3="Ç"),Tablolar!B122, IF($C$3="D",Tablolar!B158, IF($C$3="E",Tablolar!B195, IF($C$3="F",Tablolar!B231,0)))))))) | C19: =(IF($C$3=0,0,VLOOKUP(B19,IF($C$3="A",Tablolar!$B$34:$C$66,IF($C$3="B",Tablolar!$B$70:$C$113, IF(OR($C$3="C",$C$3="Ç"),Tablolar!$B$119:$C$150, IF($C$3="D",Tablolar!$B$155:$C$186, IF($C$3="E",Tablolar!$B$192:$C$223, IF($C$3="F",Tablolar!$B$228:$C$259,Tablolar!$B$264:$C$295)))))),2,FALSE)))*IF(Tablolar!A37=TRUE,1,0) -> 0 | E19: =(IF($C$3=0,"",IF($C$3="A",Tablolar!B37,IF($C$3="B",Tablolar!B73, IF(OR($C$3="C",$C$3="Ç"),Tablolar!B122, IF($C$3="D",Tablolar!B158, IF($C$3="E",Tablolar!B195, IF($C$3="F",Tablolar!B231,0)))))))) | H19: =IF(AND(Tablolar!D37=TRUE,F19=0),IF(Tablolar!D37=TRUE,VLOOKUP(E19,IF($C$3="A",Tablolar!$E$34:$H$66,IF($C$3="B",Tablolar!$E$70:$H$113,IF(OR($C$3="C",$C$3="Ç"),Tablolar!$E$119:$H$150,IF($C$3="D",Tablolar!$E$155:$H$186,IF($C$3="E",Tablolar!$E$192:$H$223,IF($C$3="F",Tablolar!$E$228:$H$259,Tablolar!$E$264:$H$295)))))),4,FALSE),0),(IF(OR($C$3=0,F19=0),0,VLOOKUP(E19,IF($C$3="A",Tablolar!$E$34:$H$66,IF($C$3="B",Tablolar!$E$70:$H$113,IF(OR($C$3="C",$C$3="Ç"),Tablolar!$E$119:$H$150,IF($C$3="D",Tablolar!$E$155:$H$186,IF($C$3="E",Tablolar!$E$192:$H$223,IF($C$3="F",Tablolar!$E$228:$H$259,Tablolar!$E$264:$H$295)))))),IF(G19/F19<0.15,2,IF(AND(G19/F19>=0.15,G19/F19<0.3),3,IF(G19/F19>=0.3,4,0))),FALSE)))) -> 0 | I19: =(IF($C$3=0,"",IF($C$3="A",Tablolar!B37,IF($C$3="B",Tablolar!B73, IF(OR($C$3="C",$C$3="Ç"),Tablolar!B122, IF($C$3="D",Tablolar!B158, IF($C$3="E",Tablolar!B195, IF($C$3="F",Tablolar!B231,0)))))))) | K19: =IF(J19="TAM", IF($C$3="A",Tablolar!K37, IF($C$3="B",Tablolar!K73, IF(OR($C$3="C",$C$3="Ç"),Tablolar!K122, IF($C$3="D",Tablolar!K158, IF($C$3="E",Tablolar!K195, IF($C$3="F",Tablolar!K231, Tablolar!K163)))))), IF(J19="LOKAL", IF($C$3="A",Tablolar!L37, IF($C$3="B",Tablolar!L73, IF(OR($C$3="C",$C$3="Ç"),Tablolar!L122, IF($C$3="D",Tablolar!L158, IF($C$3="E",Tablolar!L195, IF($C$3="F",Tablolar!L231, Tablolar!L267)))))),0)) -> 0 | M19: =IF(F16/$F$3<0.15,2,IF(AND(F16/$F$3>=0.15,F16/$F$3<0.3),3,IF(F16/$F$3>=0.3,4,0))) -> #DIV/0!
B20: =(IF($C$3=0,"",IF($C$3="A",Tablolar!B38,IF($C$3="B",Tablolar!B74, IF(OR($C$3="C",$C$3="Ç"),Tablolar!B123, IF($C$3="D",Tablolar!B159, IF($C$3="E",Tablolar!B196, IF($C$3="F",Tablolar!B232,0)))))))) | C20: =(IF($C$3=0,0,VLOOKUP(B20,IF($C$3="A",Tablolar!$B$34:$C$66,IF($C$3="B",Tablolar!$B$70:$C$113, IF(OR($C$3="C",$C$3="Ç"),Tablolar!$B$119:$C$150, IF($C$3="D",Tablolar!$B$155:$C$186, IF($C$3="E",Tablolar!$B$192:$C$223, IF($C$3="F",Tablolar!$B$228:$C$259,Tablolar!$B$264:$C$295)))))),2,FALSE)))*IF(Tablolar!A38=TRUE,1,0) -> 0 | E20: =(IF($C$3=0,"",IF($C$3="A",Tablolar!B38,IF($C$3="B",Tablolar!B74, IF(OR($C$3="C",$C$3="Ç"),Tablolar!B123, IF($C$3="D",Tablolar!B159, IF($C$3="E",Tablolar!B196, IF($C$3="F",Tablolar!B232,0)))))))) | H20: =IF(AND(Tablolar!D38=TRUE,F20=0),IF(Tablolar!D38=TRUE,VLOOKUP(E20,IF($C$3="A",Tablolar!$E$34:$H$66,IF($C$3="B",Tablolar!$E$70:$H$113,IF(OR($C$3="C",$C$3="Ç"),Tablolar!$E$119:$H$150,IF($C$3="D",Tablolar!$E$155:$H$186,IF($C$3="E",Tablolar!$E$192:$H$223,IF($C$3="F",Tablolar!$E$228:$H$259,Tablolar!$E$264:$H$295)))))),4,FALSE),0),(IF(OR($C$3=0,F20=0),0,VLOOKUP(E20,IF($C$3="A",Tablolar!$E$34:$H$66,IF($C$3="B",Tablolar!$E$70:$H$113,IF(OR($C$3="C",$C$3="Ç"),Tablolar!$E$119:$H$150,IF($C$3="D",Tablolar!$E$155:$H$186,IF($C$3="E",Tablolar!$E$192:$H$223,IF($C$3="F",Tablolar!$E$228:$H$259,Tablolar!$E$264:$H$295)))))),IF(G20/F20<0.15,2,IF(AND(G20/F20>=0.15,G20/F20<0.3),3,IF(G20/F20>=0.3,4,0))),FALSE)))) -> 0 | I20: =(IF($C$3=0,"",IF($C$3="A",Tablolar!B38,IF($C$3="B",Tablolar!B74, IF(OR($C$3="C",$C$3="Ç"),Tablolar!B123, IF($C$3="D",Tablolar!B159, IF($C$3="E",Tablolar!B196, IF($C$3="F",Tablolar!B232,0)))))))) | K20: =IF(J20="TAM", IF($C$3="A",Tablolar!K38, IF($C$3="B",Tablolar!K74, IF(OR($C$3="C",$C$3="Ç"),Tablolar!K123, IF($C$3="D",Tablolar!K159, IF($C$3="E",Tablolar!K196, IF($C$3="F",Tablolar!K232, Tablolar!K164)))))), IF(J20="LOKAL", IF($C$3="A",Tablolar!L38, IF($C$3="B",Tablolar!L74, IF(OR($C$3="C",$C$3="Ç"),Tablolar!L123, IF($C$3="D",Tablolar!L159, IF($C$3="E",Tablolar!L196, IF($C$3="F",Tablolar!L232, Tablolar!L268)))))),0)) -> 0
B21: =(IF($C$3=0,"",IF($C$3="A",Tablolar!B39,IF($C$3="B",Tablolar!B75, IF(OR($C$3="C",$C$3="Ç"),Tablolar!B124, IF($C$3="D",Tablolar!B160, IF($C$3="E",Tablolar!B197, IF($C$3="F",Tablolar!B233,0)))))))) | C21: =(IF($C$3=0,0,VLOOKUP(B21,IF($C$3="A",Tablolar!$B$34:$C$66,IF($C$3="B",Tablolar!$B$70:$C$113, IF(OR($C$3="C",$C$3="Ç"),Tablolar!$B$119:$C$150, IF($C$3="D",Tablolar!$B$155:$C$186, IF($C$3="E",Tablolar!$B$192:$C$223, IF($C$3="F",Tablolar!$B$228:$C$259,Tablolar!$B$264:$C$295)))))),2,FALSE)))*IF(Tablolar!A39=TRUE,1,0) -> 0 | E21: =(IF($C$3=0,"",IF($C$3="A",Tablolar!B39,IF($C$3="B",Tablolar!B75, IF(OR($C$3="C",$C$3="Ç"),Tablolar!B124, IF($C$3="D",Tablolar!B160, IF($C$3="E",Tablolar!B197, IF($C$3="F",Tablolar!B233,0)))))))) | H21: =IF(AND(Tablolar!D39=TRUE,F21=0),IF(Tablolar!D39=TRUE,VLOOKUP(E21,IF($C$3="A",Tablolar!$E$34:$H$66,IF($C$3="B",Tablolar!$E$70:$H$113,IF(OR($C$3="C",$C$3="Ç"),Tablolar!$E$119:$H$150,IF($C$3="D",Tablolar!$E$155:$H$186,IF($C$3="E",Tablolar!$E$192:$H$223,IF($C$3="F",Tablolar!$E$228:$H$259,Tablolar!$E$264:$H$295)))))),4,FALSE),0),(IF(OR($C$3=0,F21=0),0,VLOOKUP(E21,IF($C$3="A",Tablolar!$E$34:$H$66,IF($C$3="B",Tablolar!$E$70:$H$113,IF(OR($C$3="C",$C$3="Ç"),Tablolar!$E$119:$H$150,IF($C$3="D",Tablolar!$E$155:$H$186,IF($C$3="E",Tablolar!$E$192:$H$223,IF($C$3="F",Tablolar!$E$228:$H$259,Tablolar!$E$264:$H$295)))))),IF(G21/F21<0.15,2,IF(AND(G21/F21>=0.15,G21/F21<0.3),3,IF(G21/F21>=0.3,4,0))),FALSE)))) -> 0 | I21: =(IF($C$3=0,"",IF($C$3="A",Tablolar!B39,IF($C$3="B",Tablolar!B75, IF(OR($C$3="C",$C$3="Ç"),Tablolar!B124, IF($C$3="D",Tablolar!B160, IF($C$3="E",Tablolar!B197, IF($C$3="F",Tablolar!B233,0)))))))) | K21: =IF(J21="TAM", IF($C$3="A",Tablolar!K39, IF($C$3="B",Tablolar!K75, IF(OR($C$3="C",$C$3="Ç"),Tablolar!K124, IF($C$3="D",Tablolar!K160, IF($C$3="E",Tablolar!K197, IF($C$3="F",Tablolar!K233, Tablolar!K165)))))), IF(J21="LOKAL", IF($C$3="A",Tablolar!L39, IF($C$3="B",Tablolar!L75, IF(OR($C$3="C",$C$3="Ç"),Tablolar!L124, IF($C$3="D",Tablolar!L160, IF($C$3="E",Tablolar!L197, IF($C$3="F",Tablolar!L233, Tablolar!L269)))))),0)) -> 0
B22: =(IF($C$3=0,"",IF($C$3="A",Tablolar!B40,IF($C$3="B",Tablolar!B76, IF(OR($C$3="C",$C$3="Ç"),Tablolar!B125, IF($C$3="D",Tablolar!B161, IF($C$3="E",Tablolar!B198, IF($C$3="F",Tablolar!B234,0)))))))) | C22: =(IF($C$3=0,0,VLOOKUP(B22,IF($C$3="A",Tablolar!$B$34:$C$66,IF($C$3="B",Tablolar!$B$70:$C$113, IF(OR($C$3="C",$C$3="Ç"),Tablolar!$B$119:$C$150, IF($C$3="D",Tablolar!$B$155:$C$186, IF($C$3="E",Tablolar!$B$192:$C$223, IF($C$3="F",Tablolar!$B$228:$C$259,Tablolar!$B$264:$C$295)))))),2,FALSE)))*IF(Tablolar!A40=TRUE,1,0) -> 0 | E22: =(IF($C$3=0,"",IF($C$3="A",Tablolar!B40,IF($C$3="B",Tablolar!B76, IF(OR($C$3="C",$C$3="Ç"),Tablolar!B125, IF($C$3="D",Tablolar!B161, IF($C$3="E",Tablolar!B198, IF($C$3="F",Tablolar!B234,0)))))))) | H22: =IF(AND(Tablolar!D40=TRUE,F22=0),IF(Tablolar!D40=TRUE,VLOOKUP(E22,IF($C$3="A",Tablolar!$E$34:$H$66,IF($C$3="B",Tablolar!$E$70:$H$113,IF(OR($C$3="C",$C$3="Ç"),Tablolar!$E$119:$H$150,IF($C$3="D",Tablolar!$E$155:$H$186,IF($C$3="E",Tablolar!$E$192:$H$223,IF($C$3="F",Tablolar!$E$228:$H$259,Tablolar!$E$264:$H$295)))))),4,FALSE),0),(IF(OR($C$3=0,F22=0),0,VLOOKUP(E22,IF($C$3="A",Tablolar!$E$34:$H$66,IF($C$3="B",Tablolar!$E$70:$H$113,IF(OR($C$3="C",$C$3="Ç"),Tablolar!$E$119:$H$150,IF($C$3="D",Tablolar!$E$155:$H$186,IF($C$3="E",Tablolar!$E$192:$H$223,IF($C$3="F",Tablolar!$E$228:$H$259,Tablolar!$E$264:$H$295)))))),IF(G22/F22<0.15,2,IF(AND(G22/F22>=0.15,G22/F22<0.3),3,IF(G22/F22>=0.3,4,0))),FALSE)))) -> 0 | I22: =(IF($C$3=0,"",IF($C$3="A",Tablolar!B40,IF($C$3="B",Tablolar!B76, IF(OR($C$3="C",$C$3="Ç"),Tablolar!B125, IF($C$3="D",Tablolar!B161, IF($C$3="E",Tablolar!B198, IF($C$3="F",Tablolar!B234,0)))))))) | K22: =IF(J22="TAM", IF($C$3="A",Tablolar!K40, IF($C$3="B",Tablolar!K76, IF(OR($C$3="C",$C$3="Ç"),Tablolar!K125, IF($C$3="D",Tablolar!K161, IF($C$3="E",Tablolar!K198, IF($C$3="F",Tablolar!K234, Tablolar!K166)))))), IF(J22="LOKAL", IF($C$3="A",Tablolar!L40, IF($C$3="B",Tablolar!L76, IF(OR($C$3="C",$C$3="Ç"),Tablolar!L125, IF($C$3="D",Tablolar!L161, IF($C$3="E",Tablolar!L198, IF($C$3="F",Tablolar!L234, Tablolar!L270)))))),0)) -> 0
B23: =(IF($C$3=0,"",IF($C$3="A",Tablolar!B41,IF($C$3="B",Tablolar!B77, IF(OR($C$3="C",$C$3="Ç"),Tablolar!B126, IF($C$3="D",Tablolar!B162, IF($C$3="E",Tablolar!B199, IF($C$3="F",Tablolar!B235,0)))))))) | C23: =(IF($C$3=0,0,VLOOKUP(B23,IF($C$3="A",Tablolar!$B$34:$C$66,IF($C$3="B",Tablolar!$B$70:$C$113, IF(OR($C$3="C",$C$3="Ç"),Tablolar!$B$119:$C$150, IF($C$3="D",Tablolar!$B$155:$C$186, IF($C$3="E",Tablolar!$B$192:$C$223, IF($C$3="F",Tablolar!$B$228:$C$259,Tablolar!$B$264:$C$295)))))),2,FALSE)))*IF(Tablolar!A41=TRUE,1,0) -> 0 | E23: =(IF($C$3=0,"",IF($C$3="A",Tablolar!B41,IF($C$3="B",Tablolar!B77, IF(OR($C$3="C",$C$3="Ç"),Tablolar!B126, IF($C$3="D",Tablolar!B162, IF($C$3="E",Tablolar!B199, IF($C$3="F",Tablolar!B235,0)))))))) | H23: =IF(AND(Tablolar!D41=TRUE,F23=0),IF(Tablolar!D41=TRUE,VLOOKUP(E23,IF($C$3="A",Tablolar!$E$34:$H$66,IF($C$3="B",Tablolar!$E$70:$H$113,IF(OR($C$3="C",$C$3="Ç"),Tablolar!$E$119:$H$150,IF($C$3="D",Tablolar!$E$155:$H$186,IF($C$3="E",Tablolar!$E$192:$H$223,IF($C$3="F",Tablolar!$E$228:$H$259,Tablolar!$E$264:$H$295)))))),4,FALSE),0),(IF(OR($C$3=0,F23=0),0,VLOOKUP(E23,IF($C$3="A",Tablolar!$E$34:$H$66,IF($C$3="B",Tablolar!$E$70:$H$113,IF(OR($C$3="C",$C$3="Ç"),Tablolar!$E$119:$H$150,IF($C$3="D",Tablolar!$E$155:$H$186,IF($C$3="E",Tablolar!$E$192:$H$223,IF($C$3="F",Tablolar!$E$228:$H$259,Tablolar!$E$264:$H$295)))))),IF(G23/F23<0.15,2,IF(AND(G23/F23>=0.15,G23/F23<0.3),3,IF(G23/F23>=0.3,4,0))),FALSE)))) -> 0 | I23: =(IF($C$3=0,"",IF($C$3="A",Tablolar!B41,IF($C$3="B",Tablolar!B77, IF(OR($C$3="C",$C$3="Ç"),Tablolar!B126, IF($C$3="D",Tablolar!B162, IF($C$3="E",Tablolar!B199, IF($C$3="F",Tablolar!B235,0)))))))) | K23: =IF(J23="TAM", IF($C$3="A",Tablolar!K41, IF($C$3="B",Tablolar!K77, IF(OR($C$3="C",$C$3="Ç"),Tablolar!K126, IF($C$3="D",Tablolar!K162, IF($C$3="E",Tablolar!K199, IF($C$3="F",Tablolar!K235, Tablolar!K167)))))), IF(J23="LOKAL", IF($C$3="A",Tablolar!L41, IF($C$3="B",Tablolar!L77, IF(OR($C$3="C",$C$3="Ç"),Tablolar!L126, IF($C$3="D",Tablolar!L162, IF($C$3="E",Tablolar!L199, IF($C$3="F",Tablolar!L235, Tablolar!L271)))))),0)) -> 0
B24: =(IF($C$3=0,"",IF($C$3="A",Tablolar!B42,IF($C$3="B",Tablolar!B78, IF(OR($C$3="C",$C$3="Ç"),Tablolar!B127, IF($C$3="D",Tablolar!B163, IF($C$3="E",Tablolar!B200, IF($C$3="F",Tablolar!B236,0)))))))) | C24: =(IF($C$3=0,0,VLOOKUP(B24,IF($C$3="A",Tablolar!$B$34:$C$66,IF($C$3="B",Tablolar!$B$70:$C$113, IF(OR($C$3="C",$C$3="Ç"),Tablolar!$B$119:$C$150, IF($C$3="D",Tablolar!$B$155:$C$186, IF($C$3="E",Tablolar!$B$192:$C$223, IF($C$3="F",Tablolar!$B$228:$C$259,Tablolar!$B$264:$C$295)))))),2,FALSE)))*IF(Tablolar!A42=TRUE,1,0) -> 0 | E24: =(IF($C$3=0,"",IF($C$3="A",Tablolar!B42,IF($C$3="B",Tablolar!B78, IF(OR($C$3="C",$C$3="Ç"),Tablolar!B127, IF($C$3="D",Tablolar!B163, IF($C$3="E",Tablolar!B200, IF($C$3="F",Tablolar!B236,0)))))))) | H24: =IF(AND(Tablolar!D42=TRUE,F24=0),IF(Tablolar!D42=TRUE,VLOOKUP(E24,IF($C$3="A",Tablolar!$E$34:$H$66,IF($C$3="B",Tablolar!$E$70:$H$113,IF(OR($C$3="C",$C$3="Ç"),Tablolar!$E$119:$H$150,IF($C$3="D",Tablolar!$E$155:$H$186,IF($C$3="E",Tablolar!$E$192:$H$223,IF($C$3="F",Tablolar!$E$228:$H$259,Tablolar!$E$264:$H$295)))))),4,FALSE),0),(IF(OR($C$3=0,F24=0),0,VLOOKUP(E24,IF($C$3="A",Tablolar!$E$34:$H$66,IF($C$3="B",Tablolar!$E$70:$H$113,IF(OR($C$3="C",$C$3="Ç"),Tablolar!$E$119:$H$150,IF($C$3="D",Tablolar!$E$155:$H$186,IF($C$3="E",Tablolar!$E$192:$H$223,IF($C$3="F",Tablolar!$E$228:$H$259,Tablolar!$E$264:$H$295)))))),IF(G24/F24<0.15,2,IF(AND(G24/F24>=0.15,G24/F24<0.3),3,IF(G24/F24>=0.3,4,0))),FALSE)))) -> 0 | I24: =(IF($C$3=0,"",IF($C$3="A",Tablolar!B42,IF($C$3="B",Tablolar!B78, IF(OR($C$3="C",$C$3="Ç"),Tablolar!B127, IF($C$3="D",Tablolar!B163, IF($C$3="E",Tablolar!B200, IF($C$3="F",Tablolar!B236,0)))))))) | K24: =IF(J24="TAM", IF($C$3="A",Tablolar!K42, IF($C$3="B",Tablolar!K78, IF(OR($C$3="C",$C$3="Ç"),Tablolar!K127, IF($C$3="D",Tablolar!K163, IF($C$3="E",Tablolar!K200, IF($C$3="F",Tablolar!K236, Tablolar!K168)))))), IF(J24="LOKAL", IF($C$3="A",Tablolar!L42, IF($C$3="B",Tablolar!L78, IF(OR($C$3="C",$C$3="Ç"),Tablolar!L127, IF($C$3="D",Tablolar!L163, IF($C$3="E",Tablolar!L200, IF($C$3="F",Tablolar!L236, Tablolar!L272)))))),0)) -> 0
B25: =(IF($C$3=0,"",IF($C$3="A",Tablolar!B43,IF($C$3="B",Tablolar!B79, IF(OR($C$3="C",$C$3="Ç"),Tablolar!B128, IF($C$3="D",Tablolar!B164, IF($C$3="E",Tablolar!B201, IF($C$3="F",Tablolar!B237,0)))))))) | C25: =(IF($C$3=0,0,VLOOKUP(B25,IF($C$3="A",Tablolar!$B$34:$C$66,IF($C$3="B",Tablolar!$B$70:$C$113, IF(OR($C$3="C",$C$3="Ç"),Tablolar!$B$119:$C$150, IF($C$3="D",Tablolar!$B$155:$C$186, IF($C$3="E",Tablolar!$B$192:$C$223, IF($C$3="F",Tablolar!$B$228:$C$259,Tablolar!$B$264:$C$295)))))),2,FALSE)))*IF(Tablolar!A43=TRUE,1,0) -> 0 | E25: =(IF($C$3=0,"",IF($C$3="A",Tablolar!B43,IF($C$3="B",Tablolar!B79, IF(OR($C$3="C",$C$3="Ç"),Tablolar!B128, IF($C$3="D",Tablolar!B164, IF($C$3="E",Tablolar!B201, IF($C$3="F",Tablolar!B237,0)))))))) | H25: =IF(AND(Tablolar!D43=TRUE,F25=0),IF(Tablolar!D43=TRUE,VLOOKUP(E25,IF($C$3="A",Tablolar!$E$34:$H$66,IF($C$3="B",Tablolar!$E$70:$H$113,IF(OR($C$3="C",$C$3="Ç"),Tablolar!$E$119:$H$150,IF($C$3="D",Tablolar!$E$155:$H$186,IF($C$3="E",Tablolar!$E$192:$H$223,IF($C$3="F",Tablolar!$E$228:$H$259,Tablolar!$E$264:$H$295)))))),4,FALSE),0),(IF(OR($C$3=0,F25=0),0,VLOOKUP(E25,IF($C$3="A",Tablolar!$E$34:$H$66,IF($C$3="B",Tablolar!$E$70:$H$113,IF(OR($C$3="C",$C$3="Ç"),Tablolar!$E$119:$H$150,IF($C$3="D",Tablolar!$E$155:$H$186,IF($C$3="E",Tablolar!$E$192:$H$223,IF($C$3="F",Tablolar!$E$228:$H$259,Tablolar!$E$264:$H$295)))))),IF(G25/F25<0.15,2,IF(AND(G25/F25>=0.15,G25/F25<0.3),3,IF(G25/F25>=0.3,4,0))),FALSE)))) -> 0 | I25: =(IF($C$3=0,"",IF($C$3="A",Tablolar!B43,IF($C$3="B",Tablolar!B79, IF(OR($C$3="C",$C$3="Ç"),Tablolar!B128, IF($C$3="D",Tablolar!B164, IF($C$3="E",Tablolar!B201, IF($C$3="F",Tablolar!B237,0)))))))) | K25: =IF(J25="TAM", IF($C$3="A",Tablolar!K43, IF($C$3="B",Tablolar!K79, IF(OR($C$3="C",$C$3="Ç"),Tablolar!K128, IF($C$3="D",Tablolar!K164, IF($C$3="E",Tablolar!K201, IF($C$3="F",Tablolar!K237, Tablolar!K169)))))), IF(J25="LOKAL", IF($C$3="A",Tablolar!L43, IF($C$3="B",Tablolar!L79, IF(OR($C$3="C",$C$3="Ç"),Tablolar!L128, IF($C$3="D",Tablolar!L164, IF($C$3="E",Tablolar!L201, IF($C$3="F",Tablolar!L237, Tablolar!L273)))))),0)) -> 0
B26: =(IF($C$3=0,"",IF($C$3="A",Tablolar!B44,IF($C$3="B",Tablolar!B80, IF(OR($C$3="C",$C$3="Ç"),Tablolar!B129, IF($C$3="D",Tablolar!B165, IF($C$3="E",Tablolar!B202, IF($C$3="F",Tablolar!B238,0)))))))) | C26: =(IF($C$3=0,0,VLOOKUP(B26,IF($C$3="A",Tablolar!$B$34:$C$66,IF($C$3="B",Tablolar!$B$70:$C$113, IF(OR($C$3="C",$C$3="Ç"),Tablolar!$B$119:$C$150, IF($C$3="D",Tablolar!$B$155:$C$186, IF($C$3="E",Tablolar!$B$192:$C$223, IF($C$3="F",Tablolar!$B$228:$C$259,Tablolar!$B$264:$C$295)))))),2,FALSE)))*IF(Tablolar!A44=TRUE,1,0) -> 0 | E26: =(IF($C$3=0,"",IF($C$3="A",Tablolar!B44,IF($C$3="B",Tablolar!B80, IF(OR($C$3="C",$C$3="Ç"),Tablolar!B129, IF($C$3="D",Tablolar!B165, IF($C$3="E",Tablolar!B202, IF($C$3="F",Tablolar!B238,0)))))))) | H26: =IF(AND(Tablolar!D44=TRUE,F26=0),IF(Tablolar!D44=TRUE,VLOOKUP(E26,IF($C$3="A",Tablolar!$E$34:$H$66,IF($C$3="B",Tablolar!$E$70:$H$113,IF(OR($C$3="C",$C$3="Ç"),Tablolar!$E$119:$H$150,IF($C$3="D",Tablolar!$E$155:$H$186,IF($C$3="E",Tablolar!$E$192:$H$223,IF($C$3="F",Tablolar!$E$228:$H$259,Tablolar!$E$264:$H$295)))))),4,FALSE),0),(IF(OR($C$3=0,F26=0),0,VLOOKUP(E26,IF($C$3="A",Tablolar!$E$34:$H$66,IF($C$3="B",Tablolar!$E$70:$H$113,IF(OR($C$3="C",$C$3="Ç"),Tablolar!$E$119:$H$150,IF($C$3="D",Tablolar!$E$155:$H$186,IF($C$3="E",Tablolar!$E$192:$H$223,IF($C$3="F",Tablolar!$E$228:$H$259,Tablolar!$E$264:$H$295)))))),IF(G26/F26<0.15,2,IF(AND(G26/F26>=0.15,G26/F26<0.3),3,IF(G26/F26>=0.3,4,0))),FALSE)))) -> 0 | I26: =(IF($C$3=0,"",IF($C$3="A",Tablolar!B44,IF($C$3="B",Tablolar!B80, IF(OR($C$3="C",$C$3="Ç"),Tablolar!B129, IF($C$3="D",Tablolar!B165, IF($C$3="E",Tablolar!B202, IF($C$3="F",Tablolar!B238,0)))))))) | K26: =IF(J26="TAM", IF($C$3="A",Tablolar!K44, IF($C$3="B",Tablolar!K80, IF(OR($C$3="C",$C$3="Ç"),Tablolar!K129, IF($C$3="D",Tablolar!K165, IF($C$3="E",Tablolar!K202, IF($C$3="F",Tablolar!K238, Tablolar!K170)))))), IF(J26="LOKAL", IF($C$3="A",Tablolar!L44, IF($C$3="B",Tablolar!L80, IF(OR($C$3="C",$C$3="Ç"),Tablolar!L129, IF($C$3="D",Tablolar!L165, IF($C$3="E",Tablolar!L202, IF($C$3="F",Tablolar!L238, Tablolar!L274)))))),0)) -> 0
B27: =(IF($C$3=0,"",IF($C$3="A",Tablolar!B45,IF($C$3="B",Tablolar!B81, IF(OR($C$3="C",$C$3="Ç"),Tablolar!B130, IF($C$3="D",Tablolar!B166, IF($C$3="E",Tablolar!B203, IF($C$3="F",Tablolar!B239,0)))))))) | C27: =(IF($C$3=0,0,VLOOKUP(B27,IF($C$3="A",Tablolar!$B$34:$C$66,IF($C$3="B",Tablolar!$B$70:$C$113, IF(OR($C$3="C",$C$3="Ç"),Tablolar!$B$119:$C$150, IF($C$3="D",Tablolar!$B$155:$C$186, IF($C$3="E",Tablolar!$B$192:$C$223, IF($C$3="F",Tablolar!$B$228:$C$259,Tablolar!$B$264:$C$295)))))),2,FALSE)))*IF(Tablolar!A45=TRUE,1,0) -> 0 | E27: =(IF($C$3=0,"",IF($C$3="A",Tablolar!B45,IF($C$3="B",Tablolar!B81, IF(OR($C$3="C",$C$3="Ç"),Tablolar!B130, IF($C$3="D",Tablolar!B166, IF($C$3="E",Tablolar!B203, IF($C$3="F",Tablolar!B239,0)))))))) | H27: =IF(AND(Tablolar!D45=TRUE,F27=0),IF(Tablolar!D45=TRUE,VLOOKUP(E27,IF($C$3="A",Tablolar!$E$34:$H$66,IF($C$3="B",Tablolar!$E$70:$H$113,IF(OR($C$3="C",$C$3="Ç"),Tablolar!$E$119:$H$150,IF($C$3="D",Tablolar!$E$155:$H$186,IF($C$3="E",Tablolar!$E$192:$H$223,IF($C$3="F",Tablolar!$E$228:$H$259,Tablolar!$E$264:$H$295)))))),4,FALSE),0),(IF(OR($C$3=0,F27=0),0,VLOOKUP(E27,IF($C$3="A",Tablolar!$E$34:$H$66,IF($C$3="B",Tablolar!$E$70:$H$113,IF(OR($C$3="C",$C$3="Ç"),Tablolar!$E$119:$H$150,IF($C$3="D",Tablolar!$E$155:$H$186,IF($C$3="E",Tablolar!$E$192:$H$223,IF($C$3="F",Tablolar!$E$228:$H$259,Tablolar!$E$264:$H$295)))))),IF(G27/F27<0.15,2,IF(AND(G27/F27>=0.15,G27/F27<0.3),3,IF(G27/F27>=0.3,4,0))),FALSE)))) -> 0 | I27: =(IF($C$3=0,"",IF($C$3="A",Tablolar!B45,IF($C$3="B",Tablolar!B81, IF(OR($C$3="C",$C$3="Ç"),Tablolar!B130, IF($C$3="D",Tablolar!B166, IF($C$3="E",Tablolar!B203, IF($C$3="F",Tablolar!B239,0)))))))) | K27: =IF(J27="TAM", IF($C$3="A",Tablolar!K45, IF($C$3="B",Tablolar!K81, IF(OR($C$3="C",$C$3="Ç"),Tablolar!K130, IF($C$3="D",Tablolar!K166, IF($C$3="E",Tablolar!K203, IF($C$3="F",Tablolar!K239, Tablolar!K171)))))), IF(J27="LOKAL", IF($C$3="A",Tablolar!L45, IF($C$3="B",Tablolar!L81, IF(OR($C$3="C",$C$3="Ç"),Tablolar!L130, IF($C$3="D",Tablolar!L166, IF($C$3="E",Tablolar!L203, IF($C$3="F",Tablolar!L239, Tablolar!L275)))))),0)) -> 0
B28: =(IF($C$3=0,"",IF($C$3="A",Tablolar!B46,IF($C$3="B",Tablolar!B82, IF(OR($C$3="C",$C$3="Ç"),Tablolar!B131, IF($C$3="D",Tablolar!B167, IF($C$3="E",Tablolar!B204, IF($C$3="F",Tablolar!B240,0)))))))) | C28: =(IF($C$3=0,0,VLOOKUP(B28,IF($C$3="A",Tablolar!$B$34:$C$66,IF($C$3="B",Tablolar!$B$70:$C$113, IF(OR($C$3="C",$C$3="Ç"),Tablolar!$B$119:$C$150, IF($C$3="D",Tablolar!$B$155:$C$186, IF($C$3="E",Tablolar!$B$192:$C$223, IF($C$3="F",Tablolar!$B$228:$C$259,Tablolar!$B$264:$C$295)))))),2,FALSE)))*IF(Tablolar!A46=TRUE,1,0) -> 0 | E28: =(IF($C$3=0,"",IF($C$3="A",Tablolar!B46,IF($C$3="B",Tablolar!B82, IF(OR($C$3="C",$C$3="Ç"),Tablolar!B131, IF($C$3="D",Tablolar!B167, IF($C$3="E",Tablolar!B204, IF($C$3="F",Tablolar!B240,0)))))))) | H28: =IF(AND(Tablolar!D46=TRUE,F28=0),IF(Tablolar!D46=TRUE,VLOOKUP(E28,IF($C$3="A",Tablolar!$E$34:$H$66,IF($C$3="B",Tablolar!$E$70:$H$113,IF(OR($C$3="C",$C$3="Ç"),Tablolar!$E$119:$H$150,IF($C$3="D",Tablolar!$E$155:$H$186,IF($C$3="E",Tablolar!$E$192:$H$223,IF($C$3="F",Tablolar!$E$228:$H$259,Tablolar!$E$264:$H$295)))))),4,FALSE),0),(IF(OR($C$3=0,F28=0),0,VLOOKUP(E28,IF($C$3="A",Tablolar!$E$34:$H$66,IF($C$3="B",Tablolar!$E$70:$H$113,IF(OR($C$3="C",$C$3="Ç"),Tablolar!$E$119:$H$150,IF($C$3="D",Tablolar!$E$155:$H$186,IF($C$3="E",Tablolar!$E$192:$H$223,IF($C$3="F",Tablolar!$E$228:$H$259,Tablolar!$E$264:$H$295)))))),IF(G28/F28<0.15,2,IF(AND(G28/F28>=0.15,G28/F28<0.3),3,IF(G28/F28>=0.3,4,0))),FALSE)))) -> 0 | I28: =(IF($C$3=0,"",IF($C$3="A",Tablolar!B46,IF($C$3="B",Tablolar!B82, IF(OR($C$3="C",$C$3="Ç"),Tablolar!B131, IF($C$3="D",Tablolar!B167, IF($C$3="E",Tablolar!B204, IF($C$3="F",Tablolar!B240,0)))))))) | K28: =IF(J28="TAM", IF($C$3="A",Tablolar!K46, IF($C$3="B",Tablolar!K82, IF(OR($C$3="C",$C$3="Ç"),Tablolar!K131, IF($C$3="D",Tablolar!K167, IF($C$3="E",Tablolar!K204, IF($C$3="F",Tablolar!K240, Tablolar!K172)))))), IF(J28="LOKAL", IF($C$3="A",Tablolar!L46, IF($C$3="B",Tablolar!L82, IF(OR($C$3="C",$C$3="Ç"),Tablolar!L131, IF($C$3="D",Tablolar!L167, IF($C$3="E",Tablolar!L204, IF($C$3="F",Tablolar!L240, Tablolar!L276)))))),0)) -> 0
B29: =(IF($C$3=0,"",IF($C$3="A",Tablolar!B47,IF($C$3="B",Tablolar!B83, IF(OR($C$3="C",$C$3="Ç"),Tablolar!B132, IF($C$3="D",Tablolar!B168, IF($C$3="E",Tablolar!B205, IF($C$3="F",Tablolar!B241,0)))))))) | C29: =(IF($C$3=0,0,VLOOKUP(B29,IF($C$3="A",Tablolar!$B$34:$C$66,IF($C$3="B",Tablolar!$B$70:$C$113, IF(OR($C$3="C",$C$3="Ç"),Tablolar!$B$119:$C$151, IF($C$3="D",Tablolar!$B$155:$C$186, IF($C$3="E",Tablolar!$B$192:$C$223, IF($C$3="F",Tablolar!$B$228:$C$259,Tablolar!$B$264:$C$295)))))),2,FALSE)))*IF(Tablolar!A47=TRUE,1,0) -> 0 | E29: =(IF($C$3=0,"",IF($C$3="A",Tablolar!B47,IF($C$3="B",Tablolar!B83, IF(OR($C$3="C",$C$3="Ç"),Tablolar!B132, IF($C$3="D",Tablolar!B168, IF($C$3="E",Tablolar!B205, IF($C$3="F",Tablolar!B241,0)))))))) | H29: =IF(AND(Tablolar!D47=TRUE,F29=0),IF(Tablolar!D47=TRUE,VLOOKUP(E29,IF($C$3="A",Tablolar!$E$34:$H$66,IF($C$3="B",Tablolar!$E$70:$H$113,IF(OR($C$3="C",$C$3="Ç"),Tablolar!$E$119:$H$150,IF($C$3="D",Tablolar!$E$155:$H$186,IF($C$3="E",Tablolar!$E$192:$H$223,IF($C$3="F",Tablolar!$E$228:$H$259,Tablolar!$E$264:$H$295)))))),4,FALSE),0),(IF(OR($C$3=0,F29=0),0,VLOOKUP(E29,IF($C$3="A",Tablolar!$E$34:$H$66,IF($C$3="B",Tablolar!$E$70:$H$113,IF(OR($C$3="C",$C$3="Ç"),Tablolar!$E$119:$H$150,IF($C$3="D",Tablolar!$E$155:$H$186,IF($C$3="E",Tablolar!$E$192:$H$223,IF($C$3="F",Tablolar!$E$228:$H$259,Tablolar!$E$264:$H$295)))))),IF(G29/F29<0.15,2,IF(AND(G29/F29>=0.15,G29/F29<0.3),3,IF(G29/F29>=0.3,4,0))),FALSE)))) -> 0 | I29: =(IF($C$3=0,"",IF($C$3="A",Tablolar!B47,IF($C$3="B",Tablolar!B83, IF(OR($C$3="C",$C$3="Ç"),Tablolar!B132, IF($C$3="D",Tablolar!B168, IF($C$3="E",Tablolar!B205, IF($C$3="F",Tablolar!B241,0)))))))) | K29: =IF(J29="TAM", IF($C$3="A",Tablolar!K47, IF($C$3="B",Tablolar!K83, IF(OR($C$3="C",$C$3="Ç"),Tablolar!K132, IF($C$3="D",Tablolar!K168, IF($C$3="E",Tablolar!K205, IF($C$3="F",Tablolar!K241, Tablolar!K173)))))), IF(J29="LOKAL", IF($C$3="A",Tablolar!L47, IF($C$3="B",Tablolar!L83, IF(OR($C$3="C",$C$3="Ç"),Tablolar!L132, IF($C$3="D",Tablolar!L168, IF($C$3="E",Tablolar!L205, IF($C$3="F",Tablolar!L241, Tablolar!L277)))))),0)) -> 0
B30: =(IF($C$3=0,"",IF($C$3="A",Tablolar!B48,IF($C$3="B",Tablolar!B84, IF(OR($C$3="C",$C$3="Ç"),Tablolar!B133, IF($C$3="D",Tablolar!B169, IF($C$3="E",Tablolar!B206, IF($C$3="F",Tablolar!B242,0)))))))) | C30: =(IF($C$3=0,0,VLOOKUP(B30,IF($C$3="A",Tablolar!$B$34:$C$66,IF($C$3="B",Tablolar!$B$70:$C$113, IF(OR($C$3="C",$C$3="Ç"),Tablolar!$B$119:$C$152, IF($C$3="D",Tablolar!$B$155:$C$186, IF($C$3="E",Tablolar!$B$192:$C$223, IF($C$3="F",Tablolar!$B$228:$C$259,Tablolar!$B$264:$C$295)))))),2,FALSE)))*IF(Tablolar!A48=TRUE,1,0) -> 0 | E30: =(IF($C$3=0,"",IF($C$3="A",Tablolar!B48,IF($C$3="B",Tablolar!B84, IF(OR($C$3="C",$C$3="Ç"),Tablolar!B133, IF($C$3="D",Tablolar!B169, IF($C$3="E",Tablolar!B206, IF($C$3="F",Tablolar!B242,0)))))))) | H30: =IF(AND(Tablolar!D48=TRUE,F30=0),IF(Tablolar!D48=TRUE,VLOOKUP(E30,IF($C$3="A",Tablolar!$E$34:$H$66,IF($C$3="B",Tablolar!$E$70:$H$113,IF(OR($C$3="C",$C$3="Ç"),Tablolar!$E$119:$H$150,IF($C$3="D",Tablolar!$E$155:$H$186,IF($C$3="E",Tablolar!$E$192:$H$223,IF($C$3="F",Tablolar!$E$228:$H$259,Tablolar!$E$264:$H$295)))))),4,FALSE),0),(IF(OR($C$3=0,F30=0),0,VLOOKUP(E30,IF($C$3="A",Tablolar!$E$34:$H$66,IF($C$3="B",Tablolar!$E$70:$H$113,IF(OR($C$3="C",$C$3="Ç"),Tablolar!$E$119:$H$150,IF($C$3="D",Tablolar!$E$155:$H$186,IF($C$3="E",Tablolar!$E$192:$H$223,IF($C$3="F",Tablolar!$E$228:$H$259,Tablolar!$E$264:$H$295)))))),IF(G30/F30<0.15,2,IF(AND(G30/F30>=0.15,G30/F30<0.3),3,IF(G30/F30>=0.3,4,0))),FALSE)))) -> 0 | I30: =(IF($C$3=0,"",IF($C$3="A",Tablolar!B48,IF($C$3="B",Tablolar!B84, IF(OR($C$3="C",$C$3="Ç"),Tablolar!B133, IF($C$3="D",Tablolar!B169, IF($C$3="E",Tablolar!B206, IF($C$3="F",Tablolar!B242,0)))))))) | K30: =IF(J30="TAM", IF($C$3="A",Tablolar!K48, IF($C$3="B",Tablolar!K84, IF(OR($C$3="C",$C$3="Ç"),Tablolar!K133, IF($C$3="D",Tablolar!K169, IF($C$3="E",Tablolar!K206, IF($C$3="F",Tablolar!K242, Tablolar!K174)))))), IF(J30="LOKAL", IF($C$3="A",Tablolar!L48, IF($C$3="B",Tablolar!L84, IF(OR($C$3="C",$C$3="Ç"),Tablolar!L133, IF($C$3="D",Tablolar!L169, IF($C$3="E",Tablolar!L206, IF($C$3="F",Tablolar!L242, Tablolar!L278)))))),0)) -> 0
B31: =(IF($C$3=0,"",IF($C$3="A",Tablolar!B49,IF($C$3="B",Tablolar!B85, IF(AND(OR($C$3="C",$C$3="Ç"),$B$3="KAMYONET"),Tablolar!B134, IF(OR($C$3="C",$C$3="Ç"),Tablolar!B144, IF($C$3="D",Tablolar!B170, IF($C$3="E",Tablolar!B207, IF($C$3="F",Tablolar!B243,0))))))))) | C31: =(IF($C$3=0,0,VLOOKUP(B31,IF($C$3="A",Tablolar!$B$34:$C$66,IF($C$3="B",Tablolar!$B$70:$C$113, IF(OR($C$3="C",$C$3="Ç"),Tablolar!$B$119:$C$150, IF($C$3="D",Tablolar!$B$155:$C$186, IF($C$3="E",Tablolar!$B$192:$C$223, IF($C$3="F",Tablolar!$B$228:$C$259,Tablolar!$B$264:$C$295)))))),2,FALSE)))*IF(Tablolar!A49=TRUE,1,0) -> 0 | E31: =(IF($C$3=0,"",IF($C$3="A",Tablolar!B49,IF($C$3="B",Tablolar!B85, IF(AND(OR($C$3="C",$C$3="Ç"),$B$3="KAMYONET"),Tablolar!B134, IF(OR($C$3="C",$C$3="Ç"),Tablolar!B144, IF($C$3="D",Tablolar!B170, IF($C$3="E",Tablolar!B207, IF($C$3="F",Tablolar!B243,0))))))))) | H31: =IF(AND(Tablolar!D49=TRUE,F31=0),IF(Tablolar!D49=TRUE,VLOOKUP(E31,IF($C$3="A",Tablolar!$E$34:$H$66,IF($C$3="B",Tablolar!$E$70:$H$113,IF(OR($C$3="C",$C$3="Ç"),Tablolar!$E$119:$H$150,IF($C$3="D",Tablolar!$E$155:$H$186,IF($C$3="E",Tablolar!$E$192:$H$223,IF($C$3="F",Tablolar!$E$228:$H$259,Tablolar!$E$264:$H$295)))))),4,FALSE),0),(IF(OR($C$3=0,F31=0),0,VLOOKUP(E31,IF($C$3="A",Tablolar!$E$34:$H$66,IF($C$3="B",Tablolar!$E$70:$H$113,IF(OR($C$3="C",$C$3="Ç"),Tablolar!$E$119:$H$150,IF($C$3="D",Tablolar!$E$155:$H$186,IF($C$3="E",Tablolar!$E$192:$H$223,IF($C$3="F",Tablolar!$E$228:$H$259,Tablolar!$E$264:$H$295)))))),IF(G31/F31<0.15,2,IF(AND(G31/F31>=0.15,G31/F31<0.3),3,IF(G31/F31>=0.3,4,0))),FALSE)))) -> 0 | I31: =(IF($C$3=0,"",IF($C$3="A",Tablolar!B49,IF($C$3="B",Tablolar!B85, IF(AND(OR($C$3="C",$C$3="Ç"),$B$3="KAMYONET"),Tablolar!B134, IF(OR($C$3="C",$C$3="Ç"),Tablolar!B144, IF($C$3="D",Tablolar!B170, IF($C$3="E",Tablolar!B207, IF($C$3="F",Tablolar!B243,0))))))))) | K31: =IF(J31="TAM", IF($C$3="A",Tablolar!K49, IF($C$3="B",Tablolar!K85, IF(OR($C$3="C",$C$3="Ç"),Tablolar!K134, IF($C$3="D",Tablolar!K170, IF($C$3="E",Tablolar!K207, IF($C$3="F",Tablolar!K243, Tablolar!K175)))))), IF(J31="LOKAL", IF($C$3="A",Tablolar!L49, IF($C$3="B",Tablolar!L85, IF(OR($C$3="C",$C$3="Ç"),Tablolar!L134, IF($C$3="D",Tablolar!L170, IF($C$3="E",Tablolar!L207, IF($C$3="F",Tablolar!L243, Tablolar!L279)))))),0)) -> 0
B32: =(IF($C$3=0,"",IF($C$3="A",Tablolar!B50,IF($C$3="B",Tablolar!B86, IF(AND(OR($C$3="C",$C$3="Ç"),$B$3="KAMYONET"),Tablolar!B135, IF(OR($C$3="C",$C$3="Ç"),Tablolar!B145, IF($C$3="D",Tablolar!B171, IF($C$3="E",Tablolar!B208, IF($C$3="F",Tablolar!B244,0))))))))) | C32: =(IF($C$3=0,0,VLOOKUP(B32,IF($C$3="A",Tablolar!$B$34:$C$66,IF($C$3="B",Tablolar!$B$70:$C$113, IF(OR($C$3="C",$C$3="Ç"),Tablolar!$B$119:$C$150, IF($C$3="D",Tablolar!$B$155:$C$186, IF($C$3="E",Tablolar!$B$192:$C$223, IF($C$3="F",Tablolar!$B$228:$C$259,Tablolar!$B$264:$C$295)))))),2,FALSE)))*IF(Tablolar!A50=TRUE,1,0) -> 0 | E32: =(IF($C$3=0,"",IF($C$3="A",Tablolar!B50,IF($C$3="B",Tablolar!B86, IF(AND(OR($C$3="C",$C$3="Ç"),$B$3="KAMYONET"),Tablolar!B135, IF(OR($C$3="C",$C$3="Ç"),Tablolar!B145, IF($C$3="D",Tablolar!B171, IF($C$3="E",Tablolar!B208, IF($C$3="F",Tablolar!B244,0))))))))) | H32: =IF(AND(Tablolar!D50=TRUE,F32=0),IF(Tablolar!D50=TRUE,VLOOKUP(E32,IF($C$3="A",Tablolar!$E$34:$H$66,IF($C$3="B",Tablolar!$E$70:$H$113,IF(OR($C$3="C",$C$3="Ç"),Tablolar!$E$119:$H$150,IF($C$3="D",Tablolar!$E$155:$H$186,IF($C$3="E",Tablolar!$E$192:$H$223,IF($C$3="F",Tablolar!$E$228:$H$259,Tablolar!$E$264:$H$295)))))),4,FALSE),0),(IF(OR($C$3=0,F32=0),0,VLOOKUP(E32,IF($C$3="A",Tablolar!$E$34:$H$66,IF($C$3="B",Tablolar!$E$70:$H$113,IF(OR($C$3="C",$C$3="Ç"),Tablolar!$E$119:$H$150,IF($C$3="D",Tablolar!$E$155:$H$186,IF($C$3="E",Tablolar!$E$192:$H$223,IF($C$3="F",Tablolar!$E$228:$H$259,Tablolar!$E$264:$H$295)))))),IF(G32/F32<0.15,2,IF(AND(G32/F32>=0.15,G32/F32<0.3),3,IF(G32/F32>=0.3,4,0))),FALSE)))) -> 0 | I32: =(IF($C$3=0,"",IF($C$3="A",Tablolar!B50,IF($C$3="B",Tablolar!B86, IF(AND(OR($C$3="C",$C$3="Ç"),$B$3="KAMYONET"),Tablolar!B135, IF(OR($C$3="C",$C$3="Ç"),Tablolar!B145, IF($C$3="D",Tablolar!B171, IF($C$3="E",Tablolar!B208, IF($C$3="F",Tablolar!B244,0))))))))) | K32: =IF(J32="TAM", IF($C$3="A",Tablolar!K50, IF($C$3="B",Tablolar!K86, IF(OR($C$3="C",$C$3="Ç"),Tablolar!K135, IF($C$3="D",Tablolar!K171, IF($C$3="E",Tablolar!K208, IF($C$3="F",Tablolar!K244, Tablolar!K176)))))), IF(J32="LOKAL", IF($C$3="A",Tablolar!L50, IF($C$3="B",Tablolar!L86, IF(OR($C$3="C",$C$3="Ç"),Tablolar!L135, IF($C$3="D",Tablolar!L171, IF($C$3="E",Tablolar!L208, IF($C$3="F",Tablolar!L244, Tablolar!L280)))))),0)) -> 0
B33: =(IF($C$3=0,"",IF($C$3="A",Tablolar!B51,IF($C$3="B",Tablolar!B87, IF(AND(OR($C$3="C",$C$3="Ç"),$B$3="KAMYONET"),Tablolar!B136, IF(OR($C$3="C",$C$3="Ç"),Tablolar!B146, IF($C$3="D",Tablolar!B172, IF($C$3="E",Tablolar!B209, IF($C$3="F",Tablolar!B245,0))))))))) | C33: =(IF($C$3=0,0,VLOOKUP(B33,IF($C$3="A",Tablolar!$B$34:$C$66,IF($C$3="B",Tablolar!$B$70:$C$113, IF(OR($C$3="C",$C$3="Ç"),Tablolar!$B$119:$C$150, IF($C$3="D",Tablolar!$B$155:$C$186, IF($C$3="E",Tablolar!$B$192:$C$223, IF($C$3="F",Tablolar!$B$228:$C$259,Tablolar!$B$264:$C$295)))))),2,FALSE)))*IF(Tablolar!A51=TRUE,1,0) -> 0 | E33: =(IF($C$3=0,"",IF($C$3="A",Tablolar!B51,IF($C$3="B",Tablolar!B87, IF(AND(OR($C$3="C",$C$3="Ç"),$B$3="KAMYONET"),Tablolar!B136, IF(OR($C$3="C",$C$3="Ç"),Tablolar!B146, IF($C$3="D",Tablolar!B172, IF($C$3="E",Tablolar!B209, IF($C$3="F",Tablolar!B245,0))))))))) | H33: =IF(AND(Tablolar!D51=TRUE,F33=0),IF(Tablolar!D51=TRUE,VLOOKUP(E33,IF($C$3="A",Tablolar!$E$34:$H$66,IF($C$3="B",Tablolar!$E$70:$H$113,IF(OR($C$3="C",$C$3="Ç"),Tablolar!$E$119:$H$150,IF($C$3="D",Tablolar!$E$155:$H$186,IF($C$3="E",Tablolar!$E$192:$H$223,IF($C$3="F",Tablolar!$E$228:$H$259,Tablolar!$E$264:$H$295)))))),4,FALSE),0),(IF(OR($C$3=0,F33=0),0,VLOOKUP(E33,IF($C$3="A",Tablolar!$E$34:$H$66,IF($C$3="B",Tablolar!$E$70:$H$113,IF(OR($C$3="C",$C$3="Ç"),Tablolar!$E$119:$H$150,IF($C$3="D",Tablolar!$E$155:$H$186,IF($C$3="E",Tablolar!$E$192:$H$223,IF($C$3="F",Tablolar!$E$228:$H$259,Tablolar!$E$264:$H$295)))))),IF(G33/F33<0.15,2,IF(AND(G33/F33>=0.15,G33/F33<0.3),3,IF(G33/F33>=0.3,4,0))),FALSE)))) -> 0 | I33: =(IF($C$3=0,"",IF($C$3="A",Tablolar!B51,IF($C$3="B",Tablolar!B87, IF(AND(OR($C$3="C",$C$3="Ç"),$B$3="KAMYONET"),Tablolar!B136, IF(OR($C$3="C",$C$3="Ç"),Tablolar!B146, IF($C$3="D",Tablolar!B172, IF($C$3="E",Tablolar!B209, IF($C$3="F",Tablolar!B245,0))))))))) | K33: =IF(J33="TAM", IF($C$3="A",Tablolar!K51, IF($C$3="B",Tablolar!K87, IF(OR($C$3="C",$C$3="Ç"),Tablolar!K136, IF($C$3="D",Tablolar!K172, IF($C$3="E",Tablolar!K209, IF($C$3="F",Tablolar!K245, Tablolar!K177)))))), IF(J33="LOKAL", IF($C$3="A",Tablolar!L51, IF($C$3="B",Tablolar!L87, IF(OR($C$3="C",$C$3="Ç"),Tablolar!L136, IF($C$3="D",Tablolar!L172, IF($C$3="E",Tablolar!L209, IF($C$3="F",Tablolar!L245, Tablolar!L281)))))),0)) -> 0
B34: =(IF($C$3=0,"",IF($C$3="A",Tablolar!B52,IF($C$3="B",Tablolar!B88, IF(AND(OR($C$3="C",$C$3="Ç"),$B$3="KAMYONET"),Tablolar!B137, IF($C$3="D",Tablolar!B173, IF($C$3="E",Tablolar!B210, IF($C$3="F",Tablolar!B246,0)))))))) | C34: =(IF($C$3=0,0,VLOOKUP(B34,IF($C$3="A",Tablolar!$B$34:$C$66,IF($C$3="B",Tablolar!$B$70:$C$113, IF(OR($C$3="C",$C$3="Ç"),Tablolar!$B$119:$C$150, IF($C$3="D",Tablolar!$B$155:$C$186, IF($C$3="E",Tablolar!$B$192:$C$223, IF($C$3="F",Tablolar!$B$228:$C$259,Tablolar!$B$264:$C$295)))))),2,FALSE)))*IF(Tablolar!A52=TRUE,1,0) -> 0 | E34: =(IF($C$3=0,"",IF($C$3="A",Tablolar!B52,IF($C$3="B",Tablolar!B88, IF(AND(OR($C$3="C",$C$3="Ç"),$B$3="KAMYONET"),Tablolar!B137, IF($C$3="D",Tablolar!B173, IF($C$3="E",Tablolar!B210, IF($C$3="F",Tablolar!B246,0)))))))) | H34: =IF(AND(Tablolar!D52=TRUE,F34=0),IF(Tablolar!D52=TRUE,VLOOKUP(E34,IF($C$3="A",Tablolar!$E$34:$H$66,IF($C$3="B",Tablolar!$E$70:$H$113,IF(OR($C$3="C",$C$3="Ç"),Tablolar!$E$119:$H$150,IF($C$3="D",Tablolar!$E$155:$H$186,IF($C$3="E",Tablolar!$E$192:$H$223,IF($C$3="F",Tablolar!$E$228:$H$259,Tablolar!$E$264:$H$295)))))),4,FALSE),0),(IF(OR($C$3=0,F34=0),0,VLOOKUP(E34,IF($C$3="A",Tablolar!$E$34:$H$66,IF($C$3="B",Tablolar!$E$70:$H$113,IF(OR($C$3="C",$C$3="Ç"),Tablolar!$E$119:$H$150,IF($C$3="D",Tablolar!$E$155:$H$186,IF($C$3="E",Tablolar!$E$192:$H$223,IF($C$3="F",Tablolar!$E$228:$H$259,Tablolar!$E$264:$H$295)))))),IF(G34/F34<0.15,2,IF(AND(G34/F34>=0.15,G34/F34<0.3),3,IF(G34/F34>=0.3,4,0))),FALSE)))) -> 0 | I34: =(IF($C$3=0,"",IF($C$3="A",Tablolar!B52,IF($C$3="B",Tablolar!B88, IF(AND(OR($C$3="C",$C$3="Ç"),$B$3="KAMYONET"),Tablolar!B137, IF($C$3="D",Tablolar!B173, IF($C$3="E",Tablolar!B210, IF($C$3="F",Tablolar!B246,0)))))))) | K34: =IF(J34="TAM", IF($C$3="A",Tablolar!K52, IF($C$3="B",Tablolar!K88, IF(OR($C$3="C",$C$3="Ç"),Tablolar!K137, IF($C$3="D",Tablolar!K173, IF($C$3="E",Tablolar!K210, IF($C$3="F",Tablolar!K246, Tablolar!K178)))))), IF(J34="LOKAL", IF($C$3="A",Tablolar!L52, IF($C$3="B",Tablolar!L88, IF(OR($C$3="C",$C$3="Ç"),Tablolar!L137, IF($C$3="D",Tablolar!L173, IF($C$3="E",Tablolar!L210, IF($C$3="F",Tablolar!L246, Tablolar!L282)))))),0)) -> 0
B35: =(IF($C$3=0,"",IF($C$3="A",Tablolar!B53,IF($C$3="B",Tablolar!B89, IF(AND(OR($C$3="C",$C$3="Ç"),$B$3="KAMYONET"),Tablolar!B138, IF($C$3="D",Tablolar!B174, IF($C$3="E",Tablolar!B211, IF($C$3="F",Tablolar!B247,0)))))))) | C35: =(IF($C$3=0,0,VLOOKUP(B35,IF($C$3="A",Tablolar!$B$34:$C$66,IF($C$3="B",Tablolar!$B$70:$C$113, IF(OR($C$3="C",$C$3="Ç"),Tablolar!$B$119:$C$150, IF($C$3="D",Tablolar!$B$155:$C$186, IF($C$3="E",Tablolar!$B$192:$C$223, IF($C$3="F",Tablolar!$B$228:$C$259,Tablolar!$B$264:$C$295)))))),2,FALSE)))*IF(Tablolar!A53=TRUE,1,0) -> 0 | E35: =(IF($C$3=0,"",IF($C$3="A",Tablolar!B53,IF($C$3="B",Tablolar!B89, IF(AND(OR($C$3="C",$C$3="Ç"),$B$3="KAMYONET"),Tablolar!B138, IF($C$3="D",Tablolar!B174, IF($C$3="E",Tablolar!B211, IF($C$3="F",Tablolar!B247,0)))))))) | H35: =IF(AND(Tablolar!D53=TRUE,F35=0),IF(Tablolar!D53=TRUE,VLOOKUP(E35,IF($C$3="A",Tablolar!$E$34:$H$66,IF($C$3="B",Tablolar!$E$70:$H$113,IF(OR($C$3="C",$C$3="Ç"),Tablolar!$E$119:$H$150,IF($C$3="D",Tablolar!$E$155:$H$186,IF($C$3="E",Tablolar!$E$192:$H$223,IF($C$3="F",Tablolar!$E$228:$H$259,Tablolar!$E$264:$H$295)))))),4,FALSE),0),(IF(OR($C$3=0,F35=0),0,VLOOKUP(E35,IF($C$3="A",Tablolar!$E$34:$H$66,IF($C$3="B",Tablolar!$E$70:$H$113,IF(OR($C$3="C",$C$3="Ç"),Tablolar!$E$119:$H$150,IF($C$3="D",Tablolar!$E$155:$H$186,IF($C$3="E",Tablolar!$E$192:$H$223,IF($C$3="F",Tablolar!$E$228:$H$259,Tablolar!$E$264:$H$295)))))),IF(G35/F35<0.15,2,IF(AND(G35/F35>=0.15,G35/F35<0.3),3,IF(G35/F35>=0.3,4,0))),FALSE)))) -> 0 | I35: =(IF($C$3=0,"",IF($C$3="A",Tablolar!B53,IF($C$3="B",Tablolar!B89, IF(AND(OR($C$3="C",$C$3="Ç"),$B$3="KAMYONET"),Tablolar!B138, IF($C$3="D",Tablolar!B174, IF($C$3="E",Tablolar!B211, IF($C$3="F",Tablolar!B247,0)))))))) | K35: =IF(J35="TAM", IF($C$3="A",Tablolar!K53, IF($C$3="B",Tablolar!K89, IF(OR($C$3="C",$C$3="Ç"),Tablolar!K138, IF($C$3="D",Tablolar!K174, IF($C$3="E",Tablolar!K211, IF($C$3="F",Tablolar!K247, Tablolar!K179)))))), IF(J35="LOKAL", IF($C$3="A",Tablolar!L53, IF($C$3="B",Tablolar!L89, IF(OR($C$3="C",$C$3="Ç"),Tablolar!L138, IF($C$3="D",Tablolar!L174, IF($C$3="E",Tablolar!L211, IF($C$3="F",Tablolar!L247, Tablolar!L283)))))),0)) -> 0
B36: =(IF($C$3=0,"",IF($C$3="A",Tablolar!B54,IF($C$3="B",Tablolar!B90, IF(AND(OR($C$3="C",$C$3="Ç"),$B$3="KAMYONET"),Tablolar!B139, IF($C$3="D",Tablolar!B175, IF($C$3="E",Tablolar!B212, IF($C$3="F",Tablolar!B248,0)))))))) | C36: =(IF($C$3=0,0,VLOOKUP(B36,IF($C$3="A",Tablolar!$B$34:$C$66,IF($C$3="B",Tablolar!$B$70:$C$113, IF(OR($C$3="C",$C$3="Ç"),Tablolar!$B$119:$C$150, IF($C$3="D",Tablolar!$B$155:$C$186, IF($C$3="E",Tablolar!$B$192:$C$223, IF($C$3="F",Tablolar!$B$228:$C$259,Tablolar!$B$264:$C$295)))))),2,FALSE)))*IF(Tablolar!A54=TRUE,1,0) -> 0 | E36: =(IF($C$3=0,"",IF($C$3="A",Tablolar!B54,IF($C$3="B",Tablolar!B90, IF(AND(OR($C$3="C",$C$3="Ç"),$B$3="KAMYONET"),Tablolar!B139, IF($C$3="D",Tablolar!B175, IF($C$3="E",Tablolar!B212, IF($C$3="F",Tablolar!B248,0)))))))) | H36: =IF(AND(Tablolar!D54=TRUE,F36=0),IF(Tablolar!D54=TRUE,VLOOKUP(E36,IF($C$3="A",Tablolar!$E$34:$H$66,IF($C$3="B",Tablolar!$E$70:$H$113,IF(OR($C$3="C",$C$3="Ç"),Tablolar!$E$119:$H$150,IF($C$3="D",Tablolar!$E$155:$H$186,IF($C$3="E",Tablolar!$E$192:$H$223,IF($C$3="F",Tablolar!$E$228:$H$259,Tablolar!$E$264:$H$295)))))),4,FALSE),0),(IF(OR($C$3=0,F36=0),0,VLOOKUP(E36,IF($C$3="A",Tablolar!$E$34:$H$66,IF($C$3="B",Tablolar!$E$70:$H$113,IF(OR($C$3="C",$C$3="Ç"),Tablolar!$E$119:$H$150,IF($C$3="D",Tablolar!$E$155:$H$186,IF($C$3="E",Tablolar!$E$192:$H$223,IF($C$3="F",Tablolar!$E$228:$H$259,Tablolar!$E$264:$H$295)))))),IF(G36/F36<0.15,2,IF(AND(G36/F36>=0.15,G36/F36<0.3),3,IF(G36/F36>=0.3,4,0))),FALSE)))) -> 0 | I36: =(IF($C$3=0,"",IF($C$3="A",Tablolar!B54,IF($C$3="B",Tablolar!B90, IF(AND(OR($C$3="C",$C$3="Ç"),$B$3="KAMYONET"),Tablolar!B139, IF($C$3="D",Tablolar!B175, IF($C$3="E",Tablolar!B212, IF($C$3="F",Tablolar!B248,0)))))))) | K36: =IF(J36="TAM", IF($C$3="A",Tablolar!K54, IF($C$3="B",Tablolar!K90, IF(OR($C$3="C",$C$3="Ç"),Tablolar!K139, IF($C$3="D",Tablolar!K175, IF($C$3="E",Tablolar!K212, IF($C$3="F",Tablolar!K248, Tablolar!K180)))))), IF(J36="LOKAL", IF($C$3="A",Tablolar!L54, IF($C$3="B",Tablolar!L90, IF(OR($C$3="C",$C$3="Ç"),Tablolar!L139, IF($C$3="D",Tablolar!L175, IF($C$3="E",Tablolar!L212, IF($C$3="F",Tablolar!L248, Tablolar!L284)))))),0)) -> 0
B37: =(IF($C$3=0,"",IF($C$3="A",Tablolar!B55,IF($C$3="B",Tablolar!B91, IF(AND(OR($C$3="C",$C$3="Ç"),$B$3="KAMYONET"),Tablolar!B140, IF($C$3="D",Tablolar!B176, IF($C$3="E",Tablolar!B213, IF($C$3="F",Tablolar!B249,0)))))))) | C37: =(IF($C$3=0,0,VLOOKUP(B37,IF($C$3="A",Tablolar!$B$34:$C$66,IF($C$3="B",Tablolar!$B$70:$C$113, IF(OR($C$3="C",$C$3="Ç"),Tablolar!$B$119:$C$150, IF($C$3="D",Tablolar!$B$155:$C$186, IF($C$3="E",Tablolar!$B$192:$C$223, IF($C$3="F",Tablolar!$B$228:$C$259,Tablolar!$B$264:$C$295)))))),2,FALSE)))*IF(Tablolar!A55=TRUE,1,0) -> 0 | E37: =(IF($C$3=0,"",IF($C$3="A",Tablolar!B55,IF($C$3="B",Tablolar!B91, IF(AND(OR($C$3="C",$C$3="Ç"),$B$3="KAMYONET"),Tablolar!B140, IF($C$3="D",Tablolar!B176, IF($C$3="E",Tablolar!B213, IF($C$3="F",Tablolar!B249,0)))))))) | H37: =IF(AND(Tablolar!D55=TRUE,F37=0),IF(Tablolar!D55=TRUE,VLOOKUP(E37,IF($C$3="A",Tablolar!$E$34:$H$66,IF($C$3="B",Tablolar!$E$70:$H$113,IF(OR($C$3="C",$C$3="Ç"),Tablolar!$E$119:$H$150,IF($C$3="D",Tablolar!$E$155:$H$186,IF($C$3="E",Tablolar!$E$192:$H$223,IF($C$3="F",Tablolar!$E$228:$H$259,Tablolar!$E$264:$H$295)))))),4,FALSE),0),(IF(OR($C$3=0,F37=0),0,VLOOKUP(E37,IF($C$3="A",Tablolar!$E$34:$H$66,IF($C$3="B",Tablolar!$E$70:$H$113,IF(OR($C$3="C",$C$3="Ç"),Tablolar!$E$119:$H$150,IF($C$3="D",Tablolar!$E$155:$H$186,IF($C$3="E",Tablolar!$E$192:$H$223,IF($C$3="F",Tablolar!$E$228:$H$259,Tablolar!$E$264:$H$295)))))),IF(G37/F37<0.15,2,IF(AND(G37/F37>=0.15,G37/F37<0.3),3,IF(G37/F37>=0.3,4,0))),FALSE)))) -> 0 | I37: =(IF($C$3=0,"",IF($C$3="A",Tablolar!B55,IF($C$3="B",Tablolar!B91, IF(AND(OR($C$3="C",$C$3="Ç"),$B$3="KAMYONET"),Tablolar!B140, IF($C$3="D",Tablolar!B176, IF($C$3="E",Tablolar!B213, IF($C$3="F",Tablolar!B249,0)))))))) | K37: =IF(J37="TAM", IF($C$3="A",Tablolar!K55, IF($C$3="B",Tablolar!K91, IF(OR($C$3="C",$C$3="Ç"),Tablolar!K140, IF($C$3="D",Tablolar!K176, IF($C$3="E",Tablolar!K213, IF($C$3="F",Tablolar!K249, Tablolar!K181)))))), IF(J37="LOKAL", IF($C$3="A",Tablolar!L55, IF($C$3="B",Tablolar!L91, IF(OR($C$3="C",$C$3="Ç"),Tablolar!L140, IF($C$3="D",Tablolar!L176, IF($C$3="E",Tablolar!L213, IF($C$3="F",Tablolar!L249, Tablolar!L285)))))),0)) -> 0
B38: =(IF($C$3=0,"",IF($C$3="A",Tablolar!B56,IF($C$3="B",Tablolar!B92, IF(AND(OR($C$3="C",$C$3="Ç"),$B$3="KAMYONET"),Tablolar!B141, IF($C$3="D",Tablolar!B177, IF($C$3="E",Tablolar!B214, IF($C$3="F",Tablolar!B250,0)))))))) | C38: =(IF($C$3=0,0,VLOOKUP(B38,IF($C$3="A",Tablolar!$B$34:$C$66,IF($C$3="B",Tablolar!$B$70:$C$113, IF(OR($C$3="C",$C$3="Ç"),Tablolar!$B$119:$C$150, IF($C$3="D",Tablolar!$B$155:$C$186, IF($C$3="E",Tablolar!$B$192:$C$223, IF($C$3="F",Tablolar!$B$228:$C$259,Tablolar!$B$264:$C$295)))))),2,FALSE)))*IF(Tablolar!A56=TRUE,1,0) -> 0 | E38: =(IF($C$3=0,"",IF($C$3="A",Tablolar!B56,IF($C$3="B",Tablolar!B92, IF(AND(OR($C$3="C",$C$3="Ç"),$B$3="KAMYONET"),Tablolar!B141, IF($C$3="D",Tablolar!B177, IF($C$3="E",Tablolar!B214, IF($C$3="F",Tablolar!B250,0)))))))) | H38: =IF(AND(Tablolar!D56=TRUE,F38=0),IF(Tablolar!D56=TRUE,VLOOKUP(E38,IF($C$3="A",Tablolar!$E$34:$H$66,IF($C$3="B",Tablolar!$E$70:$H$113,IF(OR($C$3="C",$C$3="Ç"),Tablolar!$E$119:$H$150,IF($C$3="D",Tablolar!$E$155:$H$186,IF($C$3="E",Tablolar!$E$192:$H$223,IF($C$3="F",Tablolar!$E$228:$H$259,Tablolar!$E$264:$H$295)))))),4,FALSE),0),(IF(OR($C$3=0,F38=0),0,VLOOKUP(E38,IF($C$3="A",Tablolar!$E$34:$H$66,IF($C$3="B",Tablolar!$E$70:$H$113,IF(OR($C$3="C",$C$3="Ç"),Tablolar!$E$119:$H$150,IF($C$3="D",Tablolar!$E$155:$H$186,IF($C$3="E",Tablolar!$E$192:$H$223,IF($C$3="F",Tablolar!$E$228:$H$259,Tablolar!$E$264:$H$295)))))),IF(G38/F38<0.15,2,IF(AND(G38/F38>=0.15,G38/F38<0.3),3,IF(G38/F38>=0.3,4,0))),FALSE)))) -> 0 | I38: =(IF($C$3=0,"",IF($C$3="A",Tablolar!B56,IF($C$3="B",Tablolar!B92, IF(AND(OR($C$3="C",$C$3="Ç"),$B$3="KAMYONET"),Tablolar!B141, IF($C$3="D",Tablolar!B177, IF($C$3="E",Tablolar!B214, IF($C$3="F",Tablolar!B250,0)))))))) | K38: =IF(J38="TAM", IF($C$3="A",Tablolar!K56, IF($C$3="B",Tablolar!K92, IF(OR($C$3="C",$C$3="Ç"),Tablolar!K141, IF($C$3="D",Tablolar!K177, IF($C$3="E",Tablolar!K214, IF($C$3="F",Tablolar!K250, Tablolar!K182)))))), IF(J38="LOKAL", IF($C$3="A",Tablolar!L56, IF($C$3="B",Tablolar!L92, IF(OR($C$3="C",$C$3="Ç"),Tablolar!L141, IF($C$3="D",Tablolar!L177, IF($C$3="E",Tablolar!L214, IF($C$3="F",Tablolar!L250, Tablolar!L286)))))),0)) -> 0
B39: =(IF($C$3=0,"",IF($C$3="A",Tablolar!B57,IF($C$3="B",Tablolar!B93, IF(AND(OR($C$3="C",$C$3="Ç"),$B$3="KAMYONET"),Tablolar!B142, IF($C$3="D",Tablolar!B178, IF($C$3="E",Tablolar!B215, IF($C$3="F",Tablolar!B251,0)))))))) | C39: =(IF($C$3=0,0,VLOOKUP(B39,IF($C$3="A",Tablolar!$B$34:$C$66,IF($C$3="B",Tablolar!$B$70:$C$113, IF(OR($C$3="C",$C$3="Ç"),Tablolar!$B$119:$C$150, IF($C$3="D",Tablolar!$B$155:$C$186, IF($C$3="E",Tablolar!$B$192:$C$223, IF($C$3="F",Tablolar!$B$228:$C$259,Tablolar!$B$264:$C$295)))))),2,FALSE)))*IF(Tablolar!A57=TRUE,1,0) -> 0 | E39: =(IF($C$3=0,"",IF($C$3="A",Tablolar!B57,IF($C$3="B",Tablolar!B93, IF(AND(OR($C$3="C",$C$3="Ç"),$B$3="KAMYONET"),Tablolar!B142, IF($C$3="D",Tablolar!B178, IF($C$3="E",Tablolar!B215, IF($C$3="F",Tablolar!B251,0)))))))) | H39: =IF(AND(Tablolar!D57=TRUE,F39=0),IF(Tablolar!D57=TRUE,VLOOKUP(E39,IF($C$3="A",Tablolar!$E$34:$H$66,IF($C$3="B",Tablolar!$E$70:$H$113,IF(OR($C$3="C",$C$3="Ç"),Tablolar!$E$119:$H$150,IF($C$3="D",Tablolar!$E$155:$H$186,IF($C$3="E",Tablolar!$E$192:$H$223,IF($C$3="F",Tablolar!$E$228:$H$259,Tablolar!$E$264:$H$295)))))),4,FALSE),0),(IF(OR($C$3=0,F39=0),0,VLOOKUP(E39,IF($C$3="A",Tablolar!$E$34:$H$66,IF($C$3="B",Tablolar!$E$70:$H$113,IF(OR($C$3="C",$C$3="Ç"),Tablolar!$E$119:$H$150,IF($C$3="D",Tablolar!$E$155:$H$186,IF($C$3="E",Tablolar!$E$192:$H$223,IF($C$3="F",Tablolar!$E$228:$H$259,Tablolar!$E$264:$H$295)))))),IF(G39/F39<0.15,2,IF(AND(G39/F39>=0.15,G39/F39<0.3),3,IF(G39/F39>=0.3,4,0))),FALSE)))) -> 0 | I39: =(IF($C$3=0,"",IF($C$3="A",Tablolar!B57,IF($C$3="B",Tablolar!B93, IF(AND(OR($C$3="C",$C$3="Ç"),$B$3="KAMYONET"),Tablolar!B142, IF($C$3="D",Tablolar!B178, IF($C$3="E",Tablolar!B215, IF($C$3="F",Tablolar!B251,0)))))))) | K39: =IF(J39="TAM", IF($C$3="A",Tablolar!K57, IF($C$3="B",Tablolar!K93, IF(OR($C$3="C",$C$3="Ç"),Tablolar!K142, IF($C$3="D",Tablolar!K178, IF($C$3="E",Tablolar!K215, IF($C$3="F",Tablolar!K251, Tablolar!K183)))))), IF(J39="LOKAL", IF($C$3="A",Tablolar!L57, IF($C$3="B",Tablolar!L93, IF(OR($C$3="C",$C$3="Ç"),Tablolar!L142, IF($C$3="D",Tablolar!L178, IF($C$3="E",Tablolar!L215, IF($C$3="F",Tablolar!L251, Tablolar!L287)))))),0)) -> 0
B40: =(IF($C$3=0,"",IF($C$3="A",Tablolar!B264,IF($C$3="B",Tablolar!B94, IF(AND(OR($C$3="C",$C$3="Ç"),$B$3="KAMYONET"),Tablolar!B143, IF($C$3="D",Tablolar!B179, IF($C$3="E",Tablolar!B216, IF($C$3="F",Tablolar!B252,0)))))))) | C40: =(IF($C$3=0,0,VLOOKUP(B40,IF($C$3="A",Tablolar!$B$264:$C$265,IF($C$3="B",Tablolar!$B$70:$C$113, IF(OR($C$3="C",$C$3="Ç"),Tablolar!$B$119:$C$150, IF($C$3="D",Tablolar!$B$155:$C$186, IF($C$3="E",Tablolar!$B$192:$C$223, IF($C$3="F",Tablolar!$B$228:$C$259,Tablolar!$B$264:$C$295)))))),2,FALSE)))*IF(Tablolar!A58=TRUE,1,0) -> 0 | E40: =(IF($C$3=0,"",IF($C$3="A",Tablolar!B264,IF($C$3="B",Tablolar!B94, IF(AND(OR($C$3="C",$C$3="Ç"),$B$3="KAMYONET"),Tablolar!B143, IF($C$3="D",Tablolar!B179, IF($C$3="E",Tablolar!B216, IF($C$3="F",Tablolar!B252,0)))))))) | H40: =IF(AND(Tablolar!D58=TRUE,F40=0),IF(Tablolar!D58=TRUE,VLOOKUP(E40,IF($C$3="A",Tablolar!$E$264:$H$265,IF($C$3="B",Tablolar!$E$70:$H$113,IF(OR($C$3="C",$C$3="Ç"),Tablolar!$E$119:$H$150,IF($C$3="D",Tablolar!$E$155:$H$186,IF($C$3="E",Tablolar!$E$192:$H$223,IF($C$3="F",Tablolar!$E$228:$H$259,Tablolar!$E$264:$H$295)))))),4,FALSE),0),(IF(OR($C$3=0,F40=0),0,VLOOKUP(E40,IF($C$3="A",Tablolar!$E$264:$H$265,IF($C$3="B",Tablolar!$E$70:$H$113,IF(OR($C$3="C",$C$3="Ç"),Tablolar!$E$119:$H$150,IF($C$3="D",Tablolar!$E$155:$H$186,IF($C$3="E",Tablolar!$E$192:$H$223,IF($C$3="F",Tablolar!$E$228:$H$259,Tablolar!$E$264:$H$295)))))),IF(G40/F40<0.15,2,IF(AND(G40/F40>=0.15,G40/F40<0.3),3,IF(G40/F40>=0.3,4,0))),FALSE)))) -> 0 | I40: =(IF($C$3=0,"",IF($C$3="A",Tablolar!B264,IF($C$3="B",Tablolar!B94, IF(AND(OR($C$3="C",$C$3="Ç"),$B$3="KAMYONET"),Tablolar!B143, IF($C$3="D",Tablolar!B179, IF($C$3="E",Tablolar!B216, IF($C$3="F",Tablolar!B252,0)))))))) | K40: =IF(J40="TAM", IF($C$3="A",Tablolar!K264, IF($C$3="B",Tablolar!K94, IF(OR($C$3="C",$C$3="Ç"),Tablolar!K143, IF($C$3="D",Tablolar!K179, IF($C$3="E",Tablolar!K216, IF($C$3="F",Tablolar!K252, Tablolar!K184)))))), IF(J40="LOKAL", IF($C$3="A",Tablolar!L264, IF($C$3="B",Tablolar!L94, IF(OR($C$3="C",$C$3="Ç"),Tablolar!L143, IF($C$3="D",Tablolar!L179, IF($C$3="E",Tablolar!L216, IF($C$3="F",Tablolar!L252, Tablolar!L288)))))),0)) -> 0
B41: =(IF($C$3=0,"",IF($C$3="A",Tablolar!B265,IF($C$3="B",Tablolar!B95, IF(AND(OR($C$3="C",$C$3="Ç"),$B$3="KAMYONET"),Tablolar!B144, IF(OR($C$3="C",$C$3="Ç"),Tablolar!B147, IF($C$3="D",Tablolar!B180, IF($C$3="E",Tablolar!B217, IF($C$3="F",Tablolar!B253,0))))))))) | C41: =(IF($C$3=0,0,VLOOKUP(B41,IF($C$3="A",Tablolar!$B$264:$C$265,IF($C$3="B",Tablolar!$B$70:$C$113, IF(OR($C$3="C",$C$3="Ç"),Tablolar!$B$119:$C$150, IF($C$3="D",Tablolar!$B$155:$C$186, IF($C$3="E",Tablolar!$B$192:$C$223, IF($C$3="F",Tablolar!$B$228:$C$259,Tablolar!$B$264:$C$295)))))),2,FALSE)))*IF(Tablolar!A59=TRUE,1,0) -> 0 | E41: =(IF($C$3=0,"",IF($C$3="A",Tablolar!B265,IF($C$3="B",Tablolar!B95, IF(AND(OR($C$3="C",$C$3="Ç"),$B$3="KAMYONET"),Tablolar!B144, IF(OR($C$3="C",$C$3="Ç"),Tablolar!B147, IF($C$3="D",Tablolar!B180, IF($C$3="E",Tablolar!B217, IF($C$3="F",Tablolar!B253,0))))))))) | H41: =IF(AND(Tablolar!D59=TRUE,F41=0),IF(Tablolar!D59=TRUE,VLOOKUP(E41,IF($C$3="A",Tablolar!$E$264:$H$265,IF($C$3="B",Tablolar!$E$70:$H$113,IF(OR($C$3="C",$C$3="Ç"),Tablolar!$E$119:$H$150,IF($C$3="D",Tablolar!$E$155:$H$186,IF($C$3="E",Tablolar!$E$192:$H$223,IF($C$3="F",Tablolar!$E$228:$H$259,Tablolar!$E$264:$H$295)))))),4,FALSE),0),(IF(OR($C$3=0,F41=0),0,VLOOKUP(E41,IF($C$3="A",Tablolar!$E$264:$H$265,IF($C$3="B",Tablolar!$E$70:$H$113,IF(OR($C$3="C",$C$3="Ç"),Tablolar!$E$119:$H$150,IF($C$3="D",Tablolar!$E$155:$H$186,IF($C$3="E",Tablolar!$E$192:$H$223,IF($C$3="F",Tablolar!$E$228:$H$259,Tablolar!$E$264:$H$295)))))),IF(G41/F41<0.15,2,IF(AND(G41/F41>=0.15,G41/F41<0.3),3,IF(G41/F41>=0.3,4,0))),FALSE)))) -> 0 | I41: =(IF($C$3=0,"",IF($C$3="A",Tablolar!B265,IF($C$3="B",Tablolar!B95, IF(AND(OR($C$3="C",$C$3="Ç"),$B$3="KAMYONET"),Tablolar!B144, IF(OR($C$3="C",$C$3="Ç"),Tablolar!B147, IF($C$3="D",Tablolar!B180, IF($C$3="E",Tablolar!B217, IF($C$3="F",Tablolar!B253,0))))))))) | K41: =IF(J41="TAM", IF($C$3="A",Tablolar!K265, IF($C$3="B",Tablolar!K95, IF(OR($C$3="C",$C$3="Ç"),Tablolar!K144, IF($C$3="D",Tablolar!K180, IF($C$3="E",Tablolar!K217, IF($C$3="F",Tablolar!K253, Tablolar!K185)))))), IF(J41="LOKAL", IF($C$3="A",Tablolar!L265, IF($C$3="B",Tablolar!L95, IF(OR($C$3="C",$C$3="Ç"),Tablolar!L144, IF($C$3="D",Tablolar!L180, IF($C$3="E",Tablolar!L217, IF($C$3="F",Tablolar!L253, Tablolar!L289)))))),0)) -> 0
